Workbook

Sheet Sheet1
A1: COD FORNECEDOR | B1: COD IMS | C1: COD DESTINO | D1: DESENHO | E1: QTDE | F1: VEICULO | G1: TIPO SATURACAO | H1: MOT
A2: 800006372 | B2: nan | D2: 75204960 | E2: 2000
A3: 800006372 | B3: nan | D3: 75275450 | E3: 2000
A4: 800006330 | B4: nan | D4: 75284800 | E4: 1600
A5: 800006372 | B5: nan | D5: 75284910 | E5: 3000
A6: 800006372 | B6: nan | D6: 75286550 | E6: 1600
A7: 800006372 | B7: nan | D7: 75520870 | E7: 2400
A8: 800006330 | B8: nan | D8: 75601970 | E8: 12000
A9: 800028458 | B9: 31775 | C9: 1080/1046 | D9: 75685870 | E9: 4900 | F9: 4 | G9: VOLUME | H9: FTL
A10: 800006372 | B10: nan | D10: 76254450 | E10: 8000
A11: 800006372 | B11: nan | D11: 131419870 | E11: 12000
A12: 800006372 | B12: nan | D12: 145075870 | E12: 6900
A13: 800006372 | B13: nan | D13: 145076870 | E13: 4400
A14: 800006372 | B14: nan | D14: 146223870 | E14: 5900
A15: 800006330 | B15: nan | D15: 463542880 | E15: 360
A16: 800005693 | B16: nan | D16: 464013560 | E16: 936
A17: 800006372 | B17: nan | D17: 464165880 | E17: 1200
A18: 800006372 | B18: nan | D18: 464298190 | E18: 2640
A19: 800006372 | B19: nan | D19: 464363850 | E19: 3400
A20: 800006372 | B20: nan | D20: 464363860 | E20: 3600
A21: 800006372 | B21: nan | D21: 464463590 | E21: 6000
... A32: 800006372 | B32: nan | D32: 468042630 | E32: 14000
A33: 800003602 | B33: 15075/49000 | C33: 1080 | D33: 468183170 | E33: 4400 | F33: 9 | G33: VOLUME | H33: FTL
A34: 800046299 | B34: 46829 | C34: 1080 | D34: 468345180 | E34: 1500 | F34: 4 | G34: VOLUME | H34: FTL
A35: 800006330 | B35: nan | D35: 468453510 | E35: 8400
A36: 800006330 | B36: nan | D36: 500104400 | E36: 12000
A37: 800006372 | B37: nan | D37: 517081520 | E37: 1000
A38: 800005693 | B38: nan | D38: 517491240 | E38: 1568
A39: 800006372 | B39: nan | D39: 517499550 | E39: 1500
A40: 800006330 | B40: nan | D40: 517600470 | E40: 3000
A41: 800006372 | B41: nan | D41: 517618240 | E41: 2500
A42: 800006372 | B42: nan | D42: 517644570 | E42: 1000
A43: 800046299 | B43: 46829 | C43: 1080 | D43: 517665080 | E43: 1500 | F43: 4 | G43: VOLUME | H43: FTL
A44: 800045091 | B44: 56589/46051 | C44: 1046 | D44: 517855160 | E44: 1128 | F44: 5 | G44: PESO | H44: FTL
A45: 800045091 | B45: 46051 | C45: 1046 | D45: 517855160 | E45: 1128 | F45: 5 | G45: PESO | H45: FTL
A46: 800046299 | B46: 46829 | C46: 1080 | D46: 517930600 | E46: 2500 | F46: 4 | G46: VOLUME | H46: FTL
A47: 800006372 | B47: nan | D47: 518069820 | E47: 2400
A48: 800006330 | B48: nan | D48: 518226020 | E48: 5000
A49: 800006330 | B49: nan | D49: 518366020 | E49: 1400
A50: 800005693 | B50: nan | D50: 518369200 | E50: 1568
...

Sheet Sheet3
A1: COD FORNECEDOR | B1: COD IMS | C1: COD DESTINO | D1: DESENHO | E1: QTDE | F1: VEICULO | G1: TIPO SATURACAO | H1: MOT | I1: Qdte
A2: 800000059 | B2: 1094/1097 | C2: 1080 | D2: 463484480 | E2: 72 | F2: 2 | G2: VOLUME | H2: FTL | I2: =_xlfn.XLOOKUP(D2,[1]PN_PROGRAMADOS!$D:$D,[1]PN_PROGRAMADOS!$F:$F) -> 72
A3: 800000059 | B3: 1094/1097 | C3: 1080 | D3: 463484490 | E3: 81 | F3: 2 | G3: VOLUME | H3: FTL | I3: =_xlfn.XLOOKUP(D3,[1]PN_PROGRAMADOS!$D:$D,[1]PN_PROGRAMADOS!$F:$F) -> 81
A4: 800000059 | B4: 1094/1097 | C4: 1080 | D4: 463546110 | E4: 80 | F4: 2 | G4: VOLUME | H4: FTL | I4: =_xlfn.XLOOKUP(D4,[1]PN_PROGRAMADOS!$D:$D,[1]PN_PROGRAMADOS!$F:$F) -> 80
A5: 800000059 | B5: 1094/1097 | C5: 1080 | D5: 463553560 | E5: 3500 | F5: 2 | G5: VOLUME | H5: FTL | I5: =_xlfn.XLOOKUP(D5,[1]PN_PROGRAMADOS!$D:$D,[1]PN_PROGRAMADOS!$F:$F) -> 3500
A6: 800000059 | B6: 1094/1097 | C6: 1080 | D6: 463554030 | E6: 10 | F6: 2 | G6: VOLUME | H6: FTL | I6: =_xlfn.XLOOKUP(D6,[1]PN_PROGRAMADOS!$D:$D,[1]PN_PROGRAMADOS!$F:$F) -> 10
A7: 800000059 | B7: 1094/1097 | C7: 1080 | D7: 463554050 | E7: 20 | F7: 2 | G7: VOLUME | H7: FTL | I7: =_xlfn.XLOOKUP(D7,[1]PN_PROGRAMADOS!$D:$D,[1]PN_PROGRAMADOS!$F:$F) -> 20
A8: 800000059 | B8: 1094/1097 | C8: 1080 | D8: 463554270 | E8: 200 | F8: 2 | G8: VOLUME | H8: FTL | I8: =_xlfn.XLOOKUP(D8,[1]PN_PROGRAMADOS!$D:$D,[1]PN_PROGRAMADOS!$F:$F) -> 200
A9: 800000059 | B9: 1094/1097 | C9: 1080 | D9: 463554280 | E9: 20 | F9: 2 | G9: VOLUME | H9: FTL | I9: =_xlfn.XLOOKUP(D9,[1]PN_PROGRAMADOS!$D:$D,[1]PN_PROGRAMADOS!$F:$F) -> 20
A10: 800000059 | B10: 1094/1097 | C10: 1080 | D10: 463554290 | E10: 200 | F10: 2 | G10: VOLUME | H10: FTL | I10: =_xlfn.XLOOKUP(D10,[1]PN_PROGRAMADOS!$D:$D,[1]PN_PROGRAMADOS!$F:$F) -> 200
A11: 800000059 | B11: 1094/1097 | C11: 1080 | D11: 463554310 | E11: 20 | F11: 2 | G11: VOLUME | H11: FTL | I11: =_xlfn.XLOOKUP(D11,[1]PN_PROGRAMADOS!$D:$D,[1]PN_PROGRAMADOS!$F:$F) -> 20
A12: 800000059 | B12: 1094/1097 | C12: 1080 | D12: 463576370 | E12: 380 | F12: 2 | G12: VOLUME | H12: FTL | I12: =_xlfn.XLOOKUP(D12,[1]PN_PROGRAMADOS!$D:$D,[1]PN_PROGRAMADOS!$F:$F) -> 380
A13: 800000059 | B13: 1094/1097 | C13: 1080 | D13: 463576670 | E13: 1500 | F13: 2 | G13: VOLUME | H13: FTL | I13: =_xlfn.XLOOKUP(D13,[1]PN_PROGRAMADOS!$D:$D,[1]PN_PROGRAMADOS!$F:$F) -> 1500
... A38: 1097 | B38: 1094/1097 | C38: 1080 | D38: 463443560 | E38: 1920 | F38: 2 | G38: VOLUME | H38: FTL | I38: =_xlfn.XLOOKUP(D38,[1]PN_PROGRAMADOS!$D:$D,[1]PN_PROGRAMADOS!$F:$F) -> 1920

Sheet FPT
A1: COD FORNECEDOR | B1: COD IMS | C1: COD DESTINO | D1: DESENHO | E1: QTDE | F1: VEICULO | G1: TIPO SATURACAO | H1: MOT
A2: 800000059 | B2: 1097 | C2: 1046 | D2: 463484480 | E2: 72 | F2: 4 | G2: VOLUME | H2: FTL | I2: =_xlfn.XLOOKUP(D2,[1]PN_PROGRAMADOS!$D:$D,[1]PN_PROGRAMADOS!$F:$F) -> 72 | K2: =_xlfn.XLOOKUP(D2,Sheet3!D:D,Sheet3!A:A) -> 800000059
A3: 800000059 | B3: 1097 | C3: 1046 | D3: 463484490 | E3: 81 | F3: 4 | G3: VOLUME | H3: FTL | I3: =_xlfn.XLOOKUP(D3,[1]PN_PROGRAMADOS!$D:$D,[1]PN_PROGRAMADOS!$F:$F) -> 81 | K3: =_xlfn.XLOOKUP(D3,Sheet3!D:D,Sheet3!A:A) -> 800000059
A4: 800000059 | B4: 1097 | C4: 1046 | D4: 463546110 | E4: 80 | F4: 4 | G4: VOLUME | H4: FTL | I4: =_xlfn.XLOOKUP(D4,[1]PN_PROGRAMADOS!$D:$D,[1]PN_PROGRAMADOS!$F:$F) -> 80 | K4: =_xlfn.XLOOKUP(D4,Sheet3!D:D,Sheet3!A:A) -> 800000059
A5: 800000059 | B5: 1097 | C5: 1046 | D5: 463553560 | E5: 3500 | F5: 4 | G5: VOLUME | H5: FTL | I5: =_xlfn.XLOOKUP(D5,[1]PN_PROGRAMADOS!$D:$D,[1]PN_PROGRAMADOS!$F:$F) -> 3500 | K5: =_xlfn.XLOOKUP(D5,Sheet3!D:D,Sheet3!A:A) -> 800000059
A6: 800000059 | B6: 1097 | C6: 1046 | D6: 463554030 | E6: 10 | F6: 4 | G6: VOLUME | H6: FTL | I6: =_xlfn.XLOOKUP(D6,[1]PN_PROGRAMADOS!$D:$D,[1]PN_PROGRAMADOS!$F:$F) -> 10 | K6: =_xlfn.XLOOKUP(D6,Sheet3!D:D,Sheet3!A:A) -> 800000059
A7: 800000059 | B7: 1097 | C7: 1046 | D7: 463554050 | E7: 20 | F7: 4 | G7: VOLUME | H7: FTL | I7: =_xlfn.XLOOKUP(D7,[1]PN_PROGRAMADOS!$D:$D,[1]PN_PROGRAMADOS!$F:$F) -> 20 | K7: =_xlfn.XLOOKUP(D7,Sheet3!D:D,Sheet3!A:A) -> 800000059
A8: 800000059 | B8: 1097 | C8: 1046 | D8: 463554270 | E8: 200 | F8: 4 | G8: VOLUME | H8: FTL | I8: =_xlfn.XLOOKUP(D8,[1]PN_PROGRAMADOS!$D:$D,[1]PN_PROGRAMADOS!$F:$F) -> 200 | K8: =_xlfn.XLOOKUP(D8,Sheet3!D:D,Sheet3!A:A) -> 800000059
A9: 800000059 | B9: 1097 | C9: 1046 | D9: 463554280 | E9: 20 | F9: 4 | G9: VOLUME | H9: FTL | I9: =_xlfn.XLOOKUP(D9,[1]PN_PROGRAMADOS!$D:$D,[1]PN_PROGRAMADOS!$F:$F) -> 20 | K9: =_xlfn.XLOOKUP(D9,Sheet3!D:D,Sheet3!A:A) -> 800000059
A10: 800000059 | B10: 1097 | C10: 1046 | D10: 463554290 | E10: 200 | F10: 4 | G10: VOLUME | H10: FTL | I10: =_xlfn.XLOOKUP(D10,[1]PN_PROGRAMADOS!$D:$D,[1]PN_PROGRAMADOS!$F:$F) -> 200 | K10: =_xlfn.XLOOKUP(D10,Sheet3!D:D,Sheet3!A:A) -> 800000059
A11: 800000059 | B11: 1097 | C11: 1046 | D11: 463554310 | E11: 20 | F11: 4 | G11: VOLUME | H11: FTL | I11: =_xlfn.XLOOKUP(D11,[1]PN_PROGRAMADOS!$D:$D,[1]PN_PROGRAMADOS!$F:$F) -> 20 | K11: =_xlfn.XLOOKUP(D11,Sheet3!D:D,Sheet3!A:A) -> 800000059
A12: 800000059 | B12: 1097 | C12: 1046 | D12: 463576370 | E12: 380 | F12: 4 | G12: VOLUME | H12: FTL | I12: =_xlfn.XLOOKUP(D12,[1]PN_PROGRAMADOS!$D:$D,[1]PN_PROGRAMADOS!$F:$F) -> 380 | K12: =_xlfn.XLOOKUP(D12,Sheet3!D:D,Sheet3!A:A) -> 800000059
A13: 800000059 | B13: 1097 | C13: 1046 | D13: 463576670 | E13: 1500 | F13: 4 | G13: VOLUME | H13: FTL | I13: =_xlfn.XLOOKUP(D13,[1]PN_PROGRAMADOS!$D:$D,[1]PN_PROGRAMADOS!$F:$F) -> 1500 | K13: =_xlfn.XLOOKUP(D13,Sheet3!D:D,Sheet3!A:A) -> 800000059
... A21: 1097 | B21: 1097 | C21: 1046 | D21: 463571360 | E21: 960 | F21: 4 | G21: VOLUME | H21: FTL | I21: =_xlfn.XLOOKUP(D21,[1]PN_PROGRAMADOS!$D:$D,[1]PN_PROGRAMADOS!$F:$F) -> 960 | K21: =_xlfn.XLOOKUP(D21,Sheet3!D:D,Sheet3!A:A) -> 1097
A22: 1097 | B22: 1097 | C22: 1046 | D22: 463602320 | E22: 1500 | F22: 4 | G22: VOLUME | H22: FTL | I22: =_xlfn.XLOOKUP(D22,[1]PN_PROGRAMADOS!$D:$D,[1]PN_PROGRAMADOS!$F:$F) -> #N/A | K22: =_xlfn.XLOOKUP(D22,Sheet3!D:D,Sheet3!A:A) -> 1097
A23: 1097 | B23: 1097 | C23: 1046 | D23: 463559530 | E23: 2000 | F23: 4 | G23: VOLUME | H23: FTL | I23: =_xlfn.XLOOKUP(D23,[1]PN_PROGRAMADOS!$D:$D,[1]PN_PROGRAMADOS!$F:$F) -> 2000 | K23: =_xlfn.XLOOKUP(D23,Sheet3!D:D,Sheet3!A:A) -> 1097
A24: 1097 | B24: 1097 | C24: 1046 | D24: 463443560 | E24: 1920 | F24: 4 | G24: VOLUME | H24: FTL | I24: =_xlfn.XLOOKUP(D24,[1]PN_PROGRAMADOS!$D:$D,[1]PN_PROGRAMADOS!$F:$F) -> 1920 | K24: =_xlfn.XLOOKUP(D24,Sheet3!D:D,Sheet3!A:A) -> 1097
