Workbook

Sheet QUINTA-FEIRA 17-07 
A1: FIRE
A2: Saturação de Transporte
A3: PEDIDO | B3: FORNECEDOR | C3: CÓDIGO (IMS) | D3: DESENHO FIAT | E3: QME | F3: DENOMINAÇÃO | G3: QUANTIDADE SOLICITADA | H3: QUANTIDADE EMBALAGENS | I3: DATA DA COLETA | J3: DATA DA SOLICITAÇÃO | K3: HORÁRIO DA COLETA
A4: FIRE | B4: ALPINO SP | C4: 20419 | D4: 552540860 | E4: 525 | F4: TUBO RÍGIDO BOMBA D'AGUA | G4: 0 | H4: =+G4/E4 -> 0 | I4: =J4+1+1 -> 46120 | J4: =TODAY() -> 46118
A5: FIRE | B5: AUTOCAM -SP | C5: 19271 | D5: 552331860 | E5: 13800 | F5: TUCHO COMANDO DE VÁLVULAS | G5: 0 | H5: =+G5/E5 -> 0 | I5: =I4 -> 46120 | J5: =TODAY() -> 46118
A6: FIRE | B6: ALUDYNE - MG | C6: 29509 | D6: 552174870 | E6: 80 | F6: TAMPA DE VÁLVULA | G6: 0 | H6: =+G6/E6 -> 0 | I6: =I5 -> 46120 | J6: =TODAY() -> 46118
A7: FIRE | B7: ALUDYNE - SP | C7: 67200 | D7: 552322380 | E7: 1200 | F7: CONJUNTO MANCAIS CABEÇOTE | G7: 0 | H7: =+G7/E7 -> 0 | I7: =I6 -> 46120 | J7: =TODAY() -> 46118
A8: FIRE | B8: ALUDYNE - SP | C8: 67200 | D8: 552316530 | E8: 1200 | F8: CONJUNTO MANCAIS CABEÇOTE | G8: 0 | H8: =+G8/E8 -> 0 | I8: =I7 -> 46120 | J8: =TODAY() -> 46118
A9: FIRE | B9: ALUDYNE - SP | C9: 67200 | D9: 552654440 | E9: 420 | F9: CONJUNTO MANCAIS BLOCO | G9: 0 | H9: =+G9/E9 -> 0 | I9: =I8 -> 46120 | J9: =TODAY() -> 46118
A10: FIRE | B10: PROPULSION SOLUTIONS* | C10: 47104 | D10: 551812300 | E10: 120 | F10: POLIA CONDUZIDA EIXO MOTOR | G10: 0 | H10: =+G10/E10 -> 0 | I10: =I9 -> 46120 | J10: =TODAY() -> 46118
A11: FIRE | B11: PROPULSION SOLUTIONS* | C11: 47104 | D11: 551812330 | E11: 120 | F11: POLIA CONDUZIDA EIXO MOTOR - D | G11: 0 | H11: =+G11/E11 -> 0 | I11: =I10 -> 46120 | J11: =TODAY() -> 46118
A12: FIRE | B12: PROPULSION SOLUTIONS* | C12: 47104 | D12: 551812350 | E12: 120 | F12: POLIA CONDUZIDA EIXO MOTOR - A | G12: 0 | H12: =+G12/E12 -> 0 | I12: =I11 -> 46120 | J12: =TODAY() -> 46118
A13: FIRE | B13: PROPULSION SOLUTIONS* | C13: 47104 | D13: 551982470 | E13: 240 | F13: POLIA CONDUZIDA | G13: 0 | H13: =+G13/E13 -> 0 | I13: =I12 -> 46120 | J13: =TODAY() -> 46118
A14: FIRE | B14: LITENS - SP | C14: 47850 | D14: 552365200 | E14: 480 | F14: ROLAMENTO TENSOR CORREIA | G14: 0 | H14: =+G14/E14 -> 0 | I14: =I13 -> 46120 | J14: =TODAY() -> 46118
A15: FIRE | B15: LITENS - SP | C15: 47850 | D15: 552260560 | E15: 2000 | F15: ROLAMENTO TENSOR CORREIA | G15: 0 | H15: =+G15/E15 -> 0 | I15: =I14 -> 46120 | J15: =TODAY() -> 46118
A16: FIRE | B16: LITENS - SP | C16: 47850 | D16: 552002110 | E16: 480 | F16: ROLAMENTO TENSOR CORREIA | G16: 0 | H16: =+G16/E16 -> 0 | I16: =I15 -> 46120 | J16: =TODAY() -> 46118
... A92: TURBO | B92: MAGNETI MARELLI SISTEMAS AUTO* | C92: 1097 | D92: 463571360 | E92: 60 | F92: COLETOR ADMISSAO T4 PL8 MOTORES: 7816, 7817 e 7818 | G92: 1380 | H92: =+G92/E92 -> 23 | I92: =I91 -> 46120 | J92: =TODAY() -> 46118
A93: TURBO | B93: MAGNETI MARELLI SISTEMAS AUTO* | C93: 1099 | D93: 463559540 | E93: 500 | F93: SISTEMA DE INJEÇÃO | G93: 0 | H93: =+G93/E93 -> 0 | I93: =I90 -> 46120 | J93: =TODAY() -> 46118
A94: TURBO | B94: MAGNETI MARELLI SISTEMAS AUTO* | C94: 1100 | D94: 463559530 | E94: 500 | F94: SISTEMA DE INJEÇÃO | G94: 0 | H94: =+G94/E94 -> 0 | I94: =I93 -> 46120 | J94: =TODAY() -> 46118
A95: TURBO | B95: APTIV MANUFATURA E SERVI. DE * | C95: 37866 | D95: 463535560 | E95: 800 | F95: CHICOTE DE INJECAO ( BRIGLIA PSA ) T3 | G95: 800 | H95: =+G95/E95 -> 1 | I95: =I94 -> 46120 | J95: =TODAY() -> 46118
A96: TURBO | B96: APTIV MANUFATURA E SERVI. DE * | C96: 37866 | D96: 463518180 | E96: 60 | F96: CHICOTE INJEÇAO (PSA) T3 | G96: 420 | H96: =+G96/E96 -> 7 | I96: =I95 -> 46120 | J96: =TODAY() -> 46118
A97: TURBO | B97: APTIV MANUFATURA E SERVI. DE * | C97: 37866 | D97: 463480050 | E97: 800 | F97: CHICOTE DE INJECAO ( BRIGLIA ) T3 | G97: 0 | H97: =+G97/E97 -> 0 | I97: =I96 -> 46120 | J97: =TODAY() -> 46118
A98: TURBO | B98: APTIV MANUFATURA E SERVI. DE * | C98: 37866 | D98: 463479660 | E98: 60 | F98: CHICOTE INJEÇAO (PSA) T3 | G98: 0 | H98: =+G98/E98 -> 0 | I98: =I97 -> 46120 | J98: =TODAY() -> 46118
A99: TURBO | B99: APTIV MANUFATURA E SERVI. DE * | C99: 37866 | D99: 463542820 | E99: 60 | F99: CHICOTE DE INJECAO | G99: 0 | H99: =+G99/E99 -> 0 | I99: =I98 -> 46120 | J99: =TODAY() -> 46118
A100: TURBO | B100: APTIV MANUFATURA E SERVI. DE * | C100: 37866 | D100: 463465610 | E100: 800 | F100: CHICOTE DE INJECAO ( BRIGLIA ) T4 | G100: 800 | H100: =+G100/E100 -> 1 | I100: =I99 -> 46120 | J100: =TODAY() -> 46118
A101: TURBO | B101: APTIV MANUFATURA E SERVI. DE * | C101: 37866 | D101: 463564200 | E101: 60 | F101: CHICOTE SISTEMA INJECAO T3 | G101: 0 | H101: =+G101/E101 -> 0 | I101: =I100 -> 46120 | J101: =TODAY() -> 46118
A102: TURBO | B102: APTIV MANUFATURA E SERVI. DE * | C102: 37866 | D102: 463568700 | E102: 60 | F102: CHICOTE DE INJECAO ( BRIGLIA ) | G102: 120 | H102: =+G102/E102 -> 2 | I102: =I101 -> 46120 | J102: =TODAY() -> 46118
A103: TURBO | B103: APTIV MANUFATURA E SERVI. DE * | C103: 37866 | D103: 463450640 | E103: 60 | F103: CHICOTE DE INJECAO (FLEX T4) | G103: 120 | H103: =+G103/E103 -> 2 | I103: =I102 -> 46120 | J103: =TODAY() -> 46118
A104: TURBO | B104: APTIV MANUFATURA E SERVI. DE * | C104: 37866 | D104: 463497920 | E104: 60 | F104: CHICOTE SISTEMA INJECAO ( FLEX )T4 | G104: 0 | H104: =+G104/E104 -> 0 | I104: =I103 -> 46120 | J104: =TODAY() -> 46118
A105: TURBO | B105: APTIV MANUFATURA E SERVI. DE * | C105: 37866 | D105: 463563850 | E105: 60 | F105: CHICOTE SISTEMA INJECAO ( FLEX )T4 | G105: 420 | H105: =+G105/E105 -> 7 | I105: =I97 -> 46120 | J105: =TODAY() -> 46118
A106: TURBO | B106: APTIV MANUFATURA E SERVI. DE * | C106: 37866 | D106: 463564120 | E106: 60 | F106: CHICOTE DE INJECAO 281 T3 PL8 | G106: 120 | H106: =+G106/E106 -> 2 | I106: =I98 -> 46120 | J106: =TODAY() -> 46118
A107: TURBO | B107: APTIV MANUFATURA E SERVI. DE * | C107: 37866 | D107: 463577620 | E107: 60 | F107: CHICOTE DE INJECAO GSE T3 ACAC PL8 (CC21/CC22) | G107: 240 | H107: =+G107/E107 -> 4 | I107: =I99 -> 46120 | J107: =TODAY() -> 46118
A108: TURBO | B108: APTIV MANUFATURA E SERVI. DE * | C108: 37866 | D108: 463578580 | E108: 60 | F108: CHICOTE DE INJECAO T3 ACAC PL8 BSG (P21/P24) | G108: 0 | H108: =+G108/E108 -> 0 | I108: =I100 -> 46120 | J108: =TODAY() -> 46118
A109: TURBO | B109: APTIV MANUFATURA E SERVI. DE * | C109: 37866 | D109: 463576540 | E109: 60 | F109: CHICOTE DE INJECAO T4 376 PL8 | G109: 0 | H109: =+G109/E109 -> 0 | I109: =I101 -> 46120 | J109: =TODAY() -> 46118
A110: TURBO | B110: APTIV MANUFATURA E SERVI. DE * | C110: 37866 | D110: 463571180 | E110: 60 | F110: CHICOTE DE INJECAO T4 PL8 | G110: 960 | H110: =+G110/E110 -> 16 | I110: =I102 -> 46120 | J110: =TODAY() -> 46118
A111: TURBO | B111: CISER FIXADORES AUTOMOTIVOS S | C111: 27951 | D111: 463385060 | E111: 800 | F111: PARAFUSO BOMBA COMBUSTIVEL | G111: 5000 | H111: =+G111/E111 -> 6.25 | I111: =I103 -> 46120 | J111: =TODAY() -> 46118
A112: TURBO | B112: CISER FIXADORES AUTOMOTIVOS S | C112: 27951 | D112: 552821660 | E112: 600 | F112: PARAFUSO DE FIXACAO - M6 X 18 | G112: 5000 | H112: =+G112/E112 -> 8.3333333 | I112: =I104 -> 46120 | J112: =TODAY() -> 46118
A113: TURBO | B113: CISER FIXADORES AUTOMOTIVOS S | C113: 27951 | D113: 552822750 | E113: 300 | F113: PARAFUSO DE FIXACAO DA BOMBA D | G113: 5000 | H113: =+G113/E113 -> 16.666667 | I113: =I105 -> 46120 | J113: =TODAY() -> 46118
A114: TURBO | B114: CISER FIXADORES AUTOMOTIVOS S | C114: 27951 | D114: 552821670 | E114: 100 | F114: PARAFUSO ESPECIAL | G114: 5000 | H114: =+G114/E114 -> 50 | I114: =I106 -> 46120 | J114: =TODAY() -> 46118
A115: TURBO | B115: CISER FIXADORES AUTOMOTIVOS S | C115: 27951 | D115: 552845970 | E115: 600 | F115: PARAFUSO ESPECIAL | G115: 5000 | H115: =+G115/E115 -> 8.3333333 | I115: =I107 -> 46120 | J115: =TODAY() -> 46118
...

Sheet 18-02 QUA
A1: FIRE
A2: Saturação de Transporte
A3: PEDIDO | B3: FORNECEDOR | C3: CÓDIGO (IMS) | D3: DESENHO FIAT | E3: QME | F3: DENOMINAÇÃO | G3: QUANTIDADE SOLICITADA | H3: QUANTIDADE EMBALAGENS | I3: DATA DA COLETA | J3: DATA DA SOLICITAÇÃO | K3: HORÁRIO DA COLETA
A4: FIRE | B4: ALPINO SP | C4: 20419 | D4: 552540860 | E4: 525 | F4: TUBO RÍGIDO BOMBA D'AGUA | G4: 0 | H4: =+G4/E4 -> 0 | I4: 46071 | J4: 46070
A5: FIRE | B5: AUTOCAM -SP | C5: 19271 | D5: 552331860 | E5: 13800 | F5: TUCHO COMANDO DE VÁLVULAS | G5: 0 | H5: =+G5/E5 -> 0 | I5: 46071 | J5: 46070
A6: FIRE | B6: ALUDYNE - MG | C6: 29509 | D6: 552174870 | E6: 80 | F6: TAMPA DE VÁLVULA | G6: 0 | H6: =+G6/E6 -> 0 | I6: 46071 | J6: 46070
A7: FIRE | B7: ALUDYNE - SP | C7: 67200 | D7: 552322380 | E7: 1200 | F7: CONJUNTO MANCAIS CABEÇOTE | G7: 0 | H7: =+G7/E7 -> 0 | I7: 46071 | J7: 46070
A8: FIRE | B8: ALUDYNE - SP | C8: 67200 | D8: 552316530 | E8: 1200 | F8: CONJUNTO MANCAIS CABEÇOTE | G8: 0 | H8: =+G8/E8 -> 0 | I8: 46071 | J8: 46070
A9: FIRE | B9: ALUDYNE - SP | C9: 67200 | D9: 552654440 | E9: 420 | F9: CONJUNTO MANCAIS BLOCO | G9: 0 | H9: =+G9/E9 -> 0 | I9: 46071 | J9: 46070
A10: FIRE | B10: MUVIQ (PROPULSION/DAYCO) | C10: 47104 | D10: 551812300 | E10: 120 | F10: POLIA CONDUZIDA EIXO MOTOR | G10: 0 | H10: =+G10/E10 -> 0 | I10: 46071 | J10: 46070
A11: FIRE | B11: MUVIQ (PROPULSION/DAYCO) | C11: 47104 | D11: 551812330 | E11: 120 | F11: POLIA CONDUZIDA EIXO MOTOR - D | G11: 0 | H11: =+G11/E11 -> 0 | I11: 46071 | J11: 46070
A12: FIRE | B12: MUVIQ (PROPULSION/DAYCO) | C12: 47104 | D12: 551812350 | E12: 120 | F12: POLIA CONDUZIDA EIXO MOTOR - A | G12: 0 | H12: =+G12/E12 -> 0 | I12: 46071 | J12: 46070
A13: FIRE | B13: MUVIQ (PROPULSION/DAYCO) | C13: 47104 | D13: 551982470 | E13: 240 | F13: POLIA CONDUZIDA | G13: 0 | H13: =+G13/E13 -> 0 | I13: 46071 | J13: 46070
A14: FIRE | B14: LITENS - SP | C14: 47850 | D14: 552365200 | E14: 480 | F14: ROLAMENTO TENSOR CORREIA | G14: 0 | H14: =+G14/E14 -> 0 | I14: 46071 | J14: 46070
A15: FIRE | B15: LITENS - SP | C15: 47850 | D15: 552260560 | E15: 2000 | F15: ROLAMENTO TENSOR CORREIA | G15: 0 | H15: =+G15/E15 -> 0 | I15: 46071 | J15: 46070
... A184: TURBO | B184: MAHLE METAL LEVE S.A | C184: 15565 | D184: 463496640 | E184: 30 | F184: TAMPA CABECOTE MOTOR COMPLETA | G184: 0 | H184: =+G184/E184 -> 0 | I184: 46071 | J184: 46070
A185: TURBO | B185: ELRING KLINGER SP | C185: 31610 | D185: 463595330 | E185: 40 | F185: TAMPA DO CABEÇOTE T3 | G185: 0 | H185: 0 | I185: 46071 | J185: 46070
A186: TURBO | B186: ELRING KLINGER SP | C186: 31610 | D186: 552822380 | E186: 600 | F186: JUNTA METALOPLASTICA | G186: 0 | H186: =+G186/E186 -> 0 | I186: 46071 | J186: 46070
A187: TURBO | B187: ELRING KLINGER SP | C187: 31610 | D187: 463572030 | E187: 600 | F187: JUNTA CABECOTE MOTOR T3 | G187: 0 | H187: =+G187/E187 -> 0 | I187: 46071 | J187: 46070
A188: TURBO | B188: ELRING KLINGER SP | C188: 31610 | D188: 463572050 | E188: 600 | F188: JUNTA DA FLANGE COLETOR DESCARGA T3 | G188: 0 | H188: =+G188/E188 -> 0 | I188: 46071 | J188: 46070
A189: TURBO | B189: ELRING KLINGER SP | C189: 31610 | D189: 552823560 | E189: 600 | F189: JUNTA METALOPLASTICA T4 | G189: 1200 | H189: =+G189/E189 -> 2 | I189: 46071 | J189: 46070
A190: TURBO | B190: ELRING KLINGER SP | C190: 31610 | D190: 463572040 | E190: 600 | F190: JUNTA CABECOTE MOTOR T4 | G190: 1680 | H190: =+G190/E190 -> 2.8 | I190: 46071 | J190: 46070
A191: TURBO | B191: ELRING KLINGER SP | C191: 31610 | D191: 463595330 | E191: 600 | F191: JUNTA DA FLANGE COLETOR DESCARGA T4 | G191: 0 | H191: =+G191/E191 -> 0 | I191: 46071 | J191: 46070
A192: TURBO | B192: MUBEA DO BRASIL LTDA | C192: 50111 | D192: 552833910 | E192: 9000 | F192: MOLA PARA VALVULA | G192: 0 | H192: =+G192/E192 -> 0 | I192: 46071 | J192: 46070
A193: TURBO | B193: OMR - COMPONENTES AUTOMOTIVOS | C193: 56589 | D193: 463384907 | E193: 30 | F193: BLOCO MOTOR INFERIOR (BEDPLATE | G193: 900 | H193: =+G193/E193 -> 30 | I193: 46071 | J193: 46070
A194: TURBO | B194: OMR - COMPONENTES AUTOMOTIVOS | C194: 56589 | D194: 463384997 | E194: 30 | F194: BLOCO MOTOR INFERIOR T4 (BEDPL | G194: 0 | H194: =+G194/E194 -> 0 | I194: 46071 | J194: 46070
A195: TURBO | B195: METALKRAFT S/A SISTEMAS AUTOM | C195: 50050 | D195: 463529270 | E195: 432 | F195: CAPA MANCAL POSTERIOR DO CABEC | G195: 0 | H195: =+G195/E195 -> 0 | I195: 46071 | J195: 46070
A196: TURBO | B196: NEUMAYER TEKFOR AUTOMOTIVE BR | C196: 30467 | D196: 552806540 | E196: 1200 | F196: PORCA | G196: 0 | H196: =+G196/E196 -> 0 | I196: 46071 | J196: 46070
A197: TURBO | B197: NEUMAYER TEKFOR AUTOMOTIVE BR | C197: 30467 | D197: 463389730 | E197: 400 | F197: PRISIONEIRO | G197: 0 | H197: =+G197/E197 -> 0 | I197: 46071 | J197: 46070
... A647: MECA | B647: METALKRAFT | C647: 50050 | D647: 552807950 | E647: 360 | F647: ESPACADOR DE ALUMINIO | G647: 0 | H647: =+G647/E647 -> 0 | I647: 46071 | J647: 46070
A648: MECA | B648: METALKRAFT | C648: 50050 | D648: 552810000 | E648: 450 | F648: FLANGE DIFERENCIAL COMPLETA | G648: 3600 | H648: =+G648/E648 -> 8 | I648: 46071 | J648: 46070 | K648: 17:00h
A649: MECA | B649: METALKRAFT | C649: 50050 | D649: 552807960 | E649: 180 | F649: TAMPA CAIXA DE CAMBIO NP | G649: 0 | H649: =+G649/E649 -> 0 | I649: 46071 | J649: 46070
A650: MECA | B650: METALKRAFT | C650: 50050 | D650: 552512680 | E650: 1800 | F650: SUPORTE EM ALUMINIO P/FIX.COMA | G650: 3600 | H650: =+G650/E650 -> 2 | I650: 46071 | J650: 46070
A651: MECA | B651: METALKRAFT | C651: 50050 | D651: 552500530 | E651: 2400 | F651: SUPORTE EM ALUMINIO P/FIX.COMA | G651: 0 | H651: =+G651/E651 -> 0 | I651: 46071 | J651: 46070
A652: MECA | B652: METALKRAFT | C652: 50050 | D652: 552807970 | E652: 180 | F652: TAMPA CAIXA DE CAMBIO SHIFT | G652: 3600 | H652: =+G652/E652 -> 20 | I652: 46071 | J652: 46070 | K652: 17:00h
A653: MECA | B653: MIBA | C653: 51625 | D653: 463458000 | E653: 1800 | F653: CUBO 5A VELOCIDADE | G653: 3600 | H653: =+G653/E653 -> 2 | I653: 46071 | J653: 46070
A654: MECA | B654: MIBA | C654: 51625 | D654: 463457980 | E654: 1600 | F654: CUBO 1A/2A VELOCIDADE | G654: 3200 | H654: =+G654/E654 -> 2 | I654: 46071 | J654: 46070
A655: MECA | B655: MIBA | C655: 51625 | D655: 463457990 | E655: 1920 | F655: CUBO 3A/4A VELOCIDADE | G655: 3480 | H655: =+G655/E655 -> 1.8125 | I655: 46071 | J655: 46070
A656: MECA | B656: MUSASHI | C656: 13093 | D656: 552679890 | E656: 150 | F656: CONJ. CAIXA DIFERENCIAL | G656: 0 | H656: =+G656/E656 -> 0 | I656: 46071 | J656: 46070
A657: MECA | B657: NEUMAYER TEKFOR | C657: 30467 | D657: 552757120 | E657: 300 | F657: PORCA FIX.ENGR.5A VEL.SOBRE AR | G657: 6000 | H657: =+G657/E657 -> 20 | I657: 46071 | J657: 46070
...

Sheet Geral
A1: FIRE
A2: Saturação de Transporte
A3: PEDIDO | B3: FORNECEDOR | C3: CÓDIGO (IMS) | D3: DESENHO FIAT | E3: QME | F3: DENOMINAÇÃO | G3: QUANTIDADE SOLICITADA | H3: QUANTIDADE EMBALAGENS | I3: DATA DA COLETA | J3: DATA DA SOLICITAÇÃO | K3: HORÁRIO DA COLETA
A4: FIRE | B4: ALPINO SP | C4: 20419 | D4: 552540860 | E4: 525 | F4: TUBO RÍGIDO BOMBA D'AGUA | G4: 0 | H4: =+G4/E4 -> 0 | I4: =J4+1 -> 46119 | J4: =TODAY() -> 46118
A5: FIRE | B5: AUTOCAM -SP | C5: 19271 | D5: 552331860 | E5: 13800 | F5: TUCHO COMANDO DE VÁLVULAS | G5: 0 | H5: =+G5/E5 -> 0 | I5: =I4 -> 46119 | J5: =TODAY() -> 46118
A6: FIRE | B6: ALUDYNE - MG | C6: 29509 | D6: 552174870 | E6: 80 | F6: TAMPA DE VÁLVULA | G6: 0 | H6: =+G6/E6 -> 0 | I6: =I5 -> 46119 | J6: =TODAY() -> 46118
A7: FIRE | B7: ALUDYNE - SP | C7: 67200 | D7: 552322380 | E7: 1200 | F7: CONJUNTO MANCAIS CABEÇOTE | G7: 0 | H7: =+G7/E7 -> 0 | I7: =I6 -> 46119 | J7: =TODAY() -> 46118
A8: FIRE | B8: ALUDYNE - SP | C8: 67200 | D8: 552316530 | E8: 1200 | F8: CONJUNTO MANCAIS CABEÇOTE | G8: 0 | H8: =+G8/E8 -> 0 | I8: =I7 -> 46119 | J8: =TODAY() -> 46118
A9: FIRE | B9: ALUDYNE - SP | C9: 67200 | D9: 552654440 | E9: 420 | F9: CONJUNTO MANCAIS BLOCO | G9: 0 | H9: =+G9/E9 -> 0 | I9: =I8 -> 46119 | J9: =TODAY() -> 46118
A10: FIRE | B10: MUVIQ (PROPULSION/DAYCO) | C10: 47104 | D10: 551812300 | E10: 120 | F10: POLIA CONDUZIDA EIXO MOTOR | G10: 0 | H10: =+G10/E10 -> 0 | I10: =I9 -> 46119 | J10: =TODAY() -> 46118
A11: FIRE | B11: MUVIQ (PROPULSION/DAYCO) | C11: 47104 | D11: 551812330 | E11: 120 | F11: POLIA CONDUZIDA EIXO MOTOR - D | G11: 0 | H11: =+G11/E11 -> 0 | I11: =I10 -> 46119 | J11: =TODAY() -> 46118
A12: FIRE | B12: MUVIQ (PROPULSION/DAYCO) | C12: 47104 | D12: 551812350 | E12: 120 | F12: POLIA CONDUZIDA EIXO MOTOR - A | G12: 0 | H12: =+G12/E12 -> 0 | I12: =I11 -> 46119 | J12: =TODAY() -> 46118
A13: FIRE | B13: MUVIQ (PROPULSION/DAYCO) | C13: 47104 | D13: 551982470 | E13: 240 | F13: POLIA CONDUZIDA | G13: 0 | H13: =+G13/E13 -> 0 | I13: =I12 -> 46119 | J13: =TODAY() -> 46118
A14: FIRE | B14: LITENS - SP | C14: 47850 | D14: 552365200 | E14: 480 | F14: ROLAMENTO TENSOR CORREIA | G14: 2400 | H14: =+G14/E14 -> 5 | I14: =I13 -> 46119 | J14: =TODAY() -> 46118
A15: FIRE | B15: LITENS - SP | C15: 47850 | D15: 552260560 | E15: 2000 | F15: ROLAMENTO TENSOR CORREIA | G15: 2000 | H15: =+G15/E15 -> 1 | I15: =I14 -> 46119 | J15: =TODAY() -> 46118
A16: FIRE | B16: LITENS - SP | C16: 47850 | D16: 552002110 | E16: 480 | F16: ROLAMENTO TENSOR CORREIA | G16: 0 | H16: =+G16/E16 -> 0 | I16: =I15 -> 46119 | J16: =TODAY() -> 46118
... A102: TURBO | B102: APTIV MANUFATURA E SERVI. DE * | C102: 37866 | D102: 463563850 | E102: 60 | F102: CHICOTE SISTEMA INJECAO ( FLEX )T4 | G102: 0 | H102: =+G102/E102 -> 0 | I102: =I101 -> 46119 | J102: =TODAY() -> 46118
A103: TURBO | B103: APTIV MANUFATURA E SERVI. DE * | C103: 37866 | D103: 463564120 | E103: 60 | F103: CHICOTE DE INJECAO 281 T3 PL8 | G103: 0 | H103: =+G103/E103 -> 0 | I103: =I96 -> 46119 | J103: =TODAY() -> 46118
A104: TURBO | B104: APTIV MANUFATURA E SERVI. DE * | C104: 37866 | D104: 463577620 | E104: 60 | F104: CHICOTE DE INJECAO GSE T3 ACAC PL8 (CC21/CC22) | G104: 60 | H104: =+G104/E104 -> 1 | I104: =I97 -> 46119 | J104: =TODAY() -> 46118
A105: TURBO | B105: APTIV MANUFATURA E SERVI. DE * | C105: 37866 | D105: 463578580 | E105: 60 | F105: CHICOTE DE INJECAO T3 ACAC PL8 BSG (P21/P24) | G105: 0 | H105: =+G105/E105 -> 0 | I105: =I98 -> 46119 | J105: =TODAY() -> 46118
A106: TURBO | B106: APTIV MANUFATURA E SERVI. DE * | C106: 37866 | D106: 463603240 | E106: 60 | F106: CHICOTE DE INJECAO T4 - 7826 | G106: 0 | H106: =+G106/E106 -> 0 | I106: =I99 -> 46119 | J106: =TODAY() -> 46118
A107: TURBO | B107: APTIV MANUFATURA E SERVI. DE * | C107: 37866 | D107: 463576540 | E107: 60 | F107: CHICOTE DE INJECAO T4 376 PL8 | G107: 0 | H107: =+G107/E107 -> 0 | I107: =I99 -> 46119 | J107: =TODAY() -> 46118
A108: TURBO | B108: APTIV MANUFATURA E SERVI. DE * | C108: 37866 | D108: 463571180 | E108: 60 | F108: CHICOTE DE INJECAO T4 PL8 | G108: 1080 | H108: =+G108/E108 -> 18 | I108: =I100 -> 46119 | J108: =TODAY() -> 46118
A109: TURBO | B109: CISER FIXADORES AUTOMOTIVOS S | C109: 27951 | D109: 463385060 | E109: 800 | F109: PARAFUSO BOMBA COMBUSTIVEL | G109: 5000 | H109: =+G109/E109 -> 6.25 | I109: =I100 -> 46119 | J109: =TODAY() -> 46118
A110: TURBO | B110: CISER FIXADORES AUTOMOTIVOS S | C110: 27951 | D110: 552821660 | E110: 600 | F110: PARAFUSO DE FIXACAO - M6 X 18 | G110: 5000 | H110: =+G110/E110 -> 8.3333333 | I110: =I101 -> 46119 | J110: =TODAY() -> 46118
A111: TURBO | B111: CISER FIXADORES AUTOMOTIVOS S | C111: 27951 | D111: 552822750 | E111: 300 | F111: PARAFUSO DE FIXACAO DA BOMBA D | G111: 5000 | H111: =+G111/E111 -> 16.666667 | I111: =I102 -> 46119 | J111: =TODAY() -> 46118
A112: TURBO | B112: CISER FIXADORES AUTOMOTIVOS S | C112: 27951 | D112: 552821670 | E112: 100 | F112: PARAFUSO ESPECIAL | G112: 5000 | H112: =+G112/E112 -> 50 | I112: =I103 -> 46119 | J112: =TODAY() -> 46118
A113: TURBO | B113: CISER FIXADORES AUTOMOTIVOS S | C113: 27951 | D113: 552845970 | E113: 600 | F113: PARAFUSO ESPECIAL | G113: 5000 | H113: =+G113/E113 -> 8.3333333 | I113: =I104 -> 46119 | J113: =TODAY() -> 46118
A114: TURBO | B114: CISER FIXADORES AUTOMOTIVOS S | C114: 27951 | D114: 552798810 | E114: 250 | F114: PARAFUSO ESPECIAL | G114: 5000 | H114: =+G114/E114 -> 20 | I114: =I105 -> 46119 | J114: =TODAY() -> 46118
A115: TURBO | B115: CISER FIXADORES AUTOMOTIVOS S | C115: 27951 | D115: 552842340 | E115: 800 | F115: PARAFUSO ESPECIAL | G115: 5000 | H115: =+G115/E115 -> 6.25 | I115: =I107 -> 46119 | J115: =TODAY() -> 46118
A116: TURBO | B116: CISER FIXADORES AUTOMOTIVOS S | C116: 27951 | D116: 552822630 | E116: 600 | F116: PARAFUSO ESPECIAL | G116: 5000 | H116: =+G116/E116 -> 8.3333333 | I116: =I108 -> 46119 | J116: =TODAY() -> 46118
A117: TURBO | B117: CISER FIXADORES AUTOMOTIVOS S | C117: 27951 | D117: 552799020 | E117: 200 | F117: PARAFUSO ESPECIAL | G117: 5000 | H117: =+G117/E117 -> 25 | I117: =I109 -> 46119 | J117: =TODAY() -> 46118
A118: TURBO | B118: CISER FIXADORES AUTOMOTIVOS S | C118: 27951 | D118: 463369240 | E118: 500 | F118: PARAFUSO ESPECIAL | G118: 5000 | H118: =+G118/E118 -> 10 | I118: =I110 -> 46119 | J118: =TODAY() -> 46118
A119: TURBO | B119: CISER FIXADORES AUTOMOTIVOS S | C119: 27951 | D119: 463398780 | E119: 400 | F119: PARAFUSO ESPECIAL M6X46 | G119: 5000 | H119: =+G119/E119 -> 12.5 | I119: =I111 -> 46119 | J119: =TODAY() -> 46118
A120: TURBO | B120: CISER FIXADORES AUTOMOTIVOS S | C120: 27951 | D120: 552822620 | E120: 800 | F120: PARAFUSO FIXACAO BOMBA DE AGUA | G120: 5000 | H120: =+G120/E120 -> 6.25 | I120: =I112 -> 46119 | J120: =TODAY() -> 46118
A121: TURBO | B121: CISER FIXADORES AUTOMOTIVOS S | C121: 27951 | D121: 463473640 | E121: 500 | F121: PARAFUSO FIXACAO COLETOR | G121: 5000 | H121: =+G121/E121 -> 10 | I121: =I113 -> 46119 | J121: =TODAY() -> 46118
A122: TURBO | B122: CISER FIXADORES AUTOMOTIVOS S | C122: 27951 | D122: 552831540 | E122: 400 | F122: PARAFUSO FIXACAO M6 X 40 | G122: 5000 | H122: =+G122/E122 -> 12.5 | I122: =I114 -> 46119 | J122: =TODAY() -> 46118
A123: TURBO | B123: CISER FIXADORES AUTOMOTIVOS S | C123: 27951 | D123: 187517280 | E123: 400 | F123: PARAFUSO M6 X 37.5 | G123: 5000 | H123: =+G123/E123 -> 12.5 | I123: =I115 -> 46119 | J123: =TODAY() -> 46118
A124: TURBO | B124: CISER FIXADORES AUTOMOTIVOS S | C124: 27951 | D124: 552822460 | E124: 650 | F124: PARAFUSO M6X14 | G124: 5000 | H124: =+G124/E124 -> 7.6923077 | I124: =I116 -> 46119 | J124: =TODAY() -> 46118
A125: TURBO | B125: CISER FIXADORES AUTOMOTIVOS S | C125: 27951 | D125: 552821610 | E125: 150 | F125: PARAFUSO M8 X 80 | G125: 5000 | H125: =+G125/E125 -> 33.333333 | I125: =I117 -> 46119 | J125: =TODAY() -> 46118
...

Sheet SABADO
A1: FIRE
A2: Saturação de Transporte
A3: PEDIDO | B3: FORNECEDOR | C3: CÓDIGO (IMS) | D3: DESENHO FIAT | E3: QME | F3: DENOMINAÇÃO | G3: QUANTIDADE SOLICITADA | H3: QUANTIDADE EMBALAGENS | I3: DATA DA COLETA | J3: DATA DA SOLICITAÇÃO | K3: HORÁRIO DA COLETA
A4: FIRE | B4: ALPINO SP | C4: 20419 | D4: 552540860 | E4: 525 | F4: TUBO RÍGIDO BOMBA D'AGUA | G4: 0 | H4: =+G4/E4 -> 0 | I4: =J4+1 -> 46119 | J4: =TODAY() -> 46118
A5: FIRE | B5: AUTOCAM -SP | C5: 19271 | D5: 552331860 | E5: 13800 | F5: TUCHO COMANDO DE VÁLVULAS | G5: 0 | H5: =+G5/E5 -> 0 | I5: =I4 -> 46119 | J5: =TODAY() -> 46118
A6: FIRE | B6: ALUDYNE - MG | C6: 29509 | D6: 552174870 | E6: 80 | F6: TAMPA DE VÁLVULA | G6: 0 | H6: =+G6/E6 -> 0 | I6: =I5 -> 46119 | J6: =TODAY() -> 46118
A7: FIRE | B7: ALUDYNE - SP | C7: 67200 | D7: 552322380 | E7: 1200 | F7: CONJUNTO MANCAIS CABEÇOTE | G7: 0 | H7: =+G7/E7 -> 0 | I7: =I6 -> 46119 | J7: =TODAY() -> 46118
A8: FIRE | B8: ALUDYNE - SP | C8: 67200 | D8: 552316530 | E8: 1200 | F8: CONJUNTO MANCAIS CABEÇOTE | G8: 0 | H8: =+G8/E8 -> 0 | I8: =I7 -> 46119 | J8: =TODAY() -> 46118
A9: FIRE | B9: ALUDYNE - SP | C9: 67200 | D9: 552654440 | E9: 420 | F9: CONJUNTO MANCAIS BLOCO | G9: 0 | H9: =+G9/E9 -> 0 | I9: =I8 -> 46119 | J9: =TODAY() -> 46118
A10: FIRE | B10: PROPULSION SOLUTIONS* | C10: 47104 | D10: 551812300 | E10: 120 | F10: POLIA CONDUZIDA EIXO MOTOR | G10: 0 | H10: =+G10/E10 -> 0 | I10: =I9 -> 46119 | J10: =TODAY() -> 46118
A11: FIRE | B11: PROPULSION SOLUTIONS* | C11: 47104 | D11: 551812330 | E11: 120 | F11: POLIA CONDUZIDA EIXO MOTOR - D | G11: 0 | H11: =+G11/E11 -> 0 | I11: =I10 -> 46119 | J11: =TODAY() -> 46118
A12: FIRE | B12: PROPULSION SOLUTIONS* | C12: 47104 | D12: 551812350 | E12: 120 | F12: POLIA CONDUZIDA EIXO MOTOR - A | G12: 0 | H12: =+G12/E12 -> 0 | I12: =I11 -> 46119 | J12: =TODAY() -> 46118
A13: FIRE | B13: PROPULSION SOLUTIONS* | C13: 47104 | D13: 551982470 | E13: 240 | F13: POLIA CONDUZIDA | G13: 0 | H13: =+G13/E13 -> 0 | I13: =I12 -> 46119 | J13: =TODAY() -> 46118
A14: FIRE | B14: LITENS - SP | C14: 47850 | D14: 552365200 | E14: 480 | F14: ROLAMENTO TENSOR CORREIA | G14: 0 | H14: =+G14/E14 -> 0 | I14: =I13 -> 46119 | J14: =TODAY() -> 46118
A15: FIRE | B15: LITENS - SP | C15: 47850 | D15: 552260560 | E15: 2000 | F15: ROLAMENTO TENSOR CORREIA | G15: 0 | H15: =+G15/E15 -> 0 | I15: =I14 -> 46119 | J15: =TODAY() -> 46118
A16: FIRE | B16: LITENS - SP | C16: 47850 | D16: 552002110 | E16: 480 | F16: ROLAMENTO TENSOR CORREIA | G16: 0 | H16: =+G16/E16 -> 0 | I16: =I15 -> 46119 | J16: =TODAY() -> 46118
... A103: TURBO | B103: APTIV MANUFATURA E SERVI. DE * | C103: 37866 | D103: 463564120 | E103: 60 | F103: CHICOTE DE INJECAO 281 T3 PL8 | G103: 0 | H103: =+G103/E103 -> 0 | I103: =I102 -> 46119 | J103: =TODAY() -> 46118
A104: TURBO | B104: APTIV MANUFATURA E SERVI. DE * | C104: 37866 | D104: 463577620 | E104: 60 | F104: CHICOTE DE INJECAO GSE T3 ACAC PL8 (CC21/CC22) | G104: 0 | H104: =+G104/E104 -> 0 | I104: =I96 -> 46119 | J104: =TODAY() -> 46118
A105: TURBO | B105: APTIV MANUFATURA E SERVI. DE * | C105: 37866 | D105: 463578580 | E105: 60 | F105: CHICOTE DE INJECAO T3 ACAC PL8 BSG (P21/P24) | G105: 0 | H105: =+G105/E105 -> 0 | I105: =I97 -> 46119 | J105: =TODAY() -> 46118
A106: TURBO | B106: APTIV MANUFATURA E SERVI. DE * | C106: 37866 | D106: 463603240 | E106: 60 | F106: CHICOTE DE INJECAO T4 - 7826 | G106: 0 | H106: =+G106/E106 -> 0 | I106: =I98 -> 46119 | J106: =TODAY() -> 46118
A107: TURBO | B107: APTIV MANUFATURA E SERVI. DE * | C107: 37866 | D107: 463576540 | E107: 60 | F107: CHICOTE DE INJECAO T4 376 PL8 | G107: 0 | H107: =+G107/E107 -> 0 | I107: =I98 -> 46119 | J107: =TODAY() -> 46118
A108: TURBO | B108: APTIV MANUFATURA E SERVI. DE * | C108: 37866 | D108: 463571180 | E108: 60 | F108: CHICOTE DE INJECAO T4 PL8 | G108: 0 | H108: =+G108/E108 -> 0 | I108: =I99 -> 46119 | J108: =TODAY() -> 46118
A109: TURBO | B109: CISER FIXADORES AUTOMOTIVOS S | C109: 27951 | D109: 463385060 | E109: 800 | F109: PARAFUSO BOMBA COMBUSTIVEL | G109: 5000 | H109: =+G109/E109 -> 6.25 | I109: =I100 -> 46119 | J109: =TODAY() -> 46118
A110: TURBO | B110: CISER FIXADORES AUTOMOTIVOS S | C110: 27951 | D110: 552821660 | E110: 600 | F110: PARAFUSO DE FIXACAO - M6 X 18 | G110: 5000 | H110: =+G110/E110 -> 8.3333333 | I110: =I101 -> 46119 | J110: =TODAY() -> 46118
A111: TURBO | B111: CISER FIXADORES AUTOMOTIVOS S | C111: 27951 | D111: 552822750 | E111: 300 | F111: PARAFUSO DE FIXACAO DA BOMBA D | G111: 5000 | H111: =+G111/E111 -> 16.666667 | I111: =I102 -> 46119 | J111: =TODAY() -> 46118
A112: TURBO | B112: CISER FIXADORES AUTOMOTIVOS S | C112: 27951 | D112: 552821670 | E112: 100 | F112: PARAFUSO ESPECIAL | G112: 5000 | H112: =+G112/E112 -> 50 | I112: =I103 -> 46119 | J112: =TODAY() -> 46118
A113: TURBO | B113: CISER FIXADORES AUTOMOTIVOS S | C113: 27951 | D113: 552845970 | E113: 600 | F113: PARAFUSO ESPECIAL | G113: 5000 | H113: =+G113/E113 -> 8.3333333 | I113: =I104 -> 46119 | J113: =TODAY() -> 46118
A114: TURBO | B114: CISER FIXADORES AUTOMOTIVOS S | C114: 27951 | D114: 552798810 | E114: 250 | F114: PARAFUSO ESPECIAL | G114: 5000 | H114: =+G114/E114 -> 20 | I114: =I105 -> 46119 | J114: =TODAY() -> 46118
A115: TURBO | B115: CISER FIXADORES AUTOMOTIVOS S | C115: 27951 | D115: 552842340 | E115: 800 | F115: PARAFUSO ESPECIAL | G115: 5000 | H115: =+G115/E115 -> 6.25 | I115: =I107 -> 46119 | J115: =TODAY() -> 46118
A116: TURBO | B116: CISER FIXADORES AUTOMOTIVOS S | C116: 27951 | D116: 552822630 | E116: 600 | F116: PARAFUSO ESPECIAL | G116: 5000 | H116: =+G116/E116 -> 8.3333333 | I116: =I108 -> 46119 | J116: =TODAY() -> 46118
A117: TURBO | B117: CISER FIXADORES AUTOMOTIVOS S | C117: 27951 | D117: 552799020 | E117: 200 | F117: PARAFUSO ESPECIAL | G117: 5000 | H117: =+G117/E117 -> 25 | I117: =I109 -> 46119 | J117: =TODAY() -> 46118
A118: TURBO | B118: CISER FIXADORES AUTOMOTIVOS S | C118: 27951 | D118: 463369240 | E118: 500 | F118: PARAFUSO ESPECIAL | G118: 5000 | H118: =+G118/E118 -> 10 | I118: =I110 -> 46119 | J118: =TODAY() -> 46118
A119: TURBO | B119: CISER FIXADORES AUTOMOTIVOS S | C119: 27951 | D119: 463398780 | E119: 400 | F119: PARAFUSO ESPECIAL M6X46 | G119: 5000 | H119: =+G119/E119 -> 12.5 | I119: =I111 -> 46119 | J119: =TODAY() -> 46118
A120: TURBO | B120: CISER FIXADORES AUTOMOTIVOS S | C120: 27951 | D120: 552822620 | E120: 800 | F120: PARAFUSO FIXACAO BOMBA DE AGUA | G120: 5000 | H120: =+G120/E120 -> 6.25 | I120: =I112 -> 46119 | J120: =TODAY() -> 46118
A121: TURBO | B121: CISER FIXADORES AUTOMOTIVOS S | C121: 27951 | D121: 463473640 | E121: 500 | F121: PARAFUSO FIXACAO COLETOR | G121: 5000 | H121: =+G121/E121 -> 10 | I121: =I113 -> 46119 | J121: =TODAY() -> 46118
A122: TURBO | B122: CISER FIXADORES AUTOMOTIVOS S | C122: 27951 | D122: 552831540 | E122: 400 | F122: PARAFUSO FIXACAO M6 X 40 | G122: 5000 | H122: =+G122/E122 -> 12.5 | I122: =I114 -> 46119 | J122: =TODAY() -> 46118
A123: TURBO | B123: CISER FIXADORES AUTOMOTIVOS S | C123: 27951 | D123: 187517280 | E123: 400 | F123: PARAFUSO M6 X 37.5 | G123: 5000 | H123: =+G123/E123 -> 12.5 | I123: =I115 -> 46119 | J123: =TODAY() -> 46118
A124: TURBO | B124: CISER FIXADORES AUTOMOTIVOS S | C124: 27951 | D124: 552822460 | E124: 650 | F124: PARAFUSO M6X14 | G124: 5000 | H124: =+G124/E124 -> 7.6923077 | I124: =I116 -> 46119 | J124: =TODAY() -> 46118
A125: TURBO | B125: CISER FIXADORES AUTOMOTIVOS S | C125: 27951 | D125: 552821610 | E125: 150 | F125: PARAFUSO M8 X 80 | G125: 5000 | H125: =+G125/E125 -> 33.333333 | I125: =I117 -> 46119 | J125: =TODAY() -> 46118
A126: TURBO | B126: CISER FIXADORES AUTOMOTIVOS S | C126: 27951 | D126: 552842370 | E126: 400 | F126: PARAFUSO TE FLANGEADO M6X30 | G126: 5000 | H126: =+G126/E126 -> 12.5 | I126: =I118 -> 46119 | J126: =TODAY() -> 46118
...

Sheet DOMINGO
A1: FIRE
A2: Saturação de Transporte
A3: PEDIDO | B3: FORNECEDOR | C3: CÓDIGO (IMS) | D3: DESENHO FIAT | E3: QME | F3: DENOMINAÇÃO | G3: QUANTIDADE SOLICITADA | H3: QUANTIDADE EMBALAGENS | I3: DATA DA COLETA | J3: DATA DA SOLICITAÇÃO | K3: HORÁRIO DA COLETA
A4: FIRE | B4: ALPINO SP | C4: 20419 | D4: 552540860 | E4: 525 | F4: TUBO RÍGIDO BOMBA D'AGUA | G4: 0 | H4: =+G4/E4 -> 0 | I4: =J4+2 -> 46120 | J4: =TODAY() -> 46118
A5: FIRE | B5: AUTOCAM -SP | C5: 19271 | D5: 552331860 | E5: 13800 | F5: TUCHO COMANDO DE VÁLVULAS | G5: 0 | H5: =+G5/E5 -> 0 | I5: =I4 -> 46120 | J5: =TODAY() -> 46118
A6: FIRE | B6: ALUDYNE - MG | C6: 29509 | D6: 552174870 | E6: 80 | F6: TAMPA DE VÁLVULA | G6: 0 | H6: =+G6/E6 -> 0 | I6: =I5 -> 46120 | J6: =TODAY() -> 46118
A7: FIRE | B7: ALUDYNE - SP | C7: 67200 | D7: 552322380 | E7: 1200 | F7: CONJUNTO MANCAIS CABEÇOTE | G7: 0 | H7: =+G7/E7 -> 0 | I7: =I6 -> 46120 | J7: =TODAY() -> 46118
A8: FIRE | B8: ALUDYNE - SP | C8: 67200 | D8: 552316530 | E8: 1200 | F8: CONJUNTO MANCAIS CABEÇOTE | G8: 0 | H8: =+G8/E8 -> 0 | I8: =I7 -> 46120 | J8: =TODAY() -> 46118
A9: FIRE | B9: ALUDYNE - SP | C9: 67200 | D9: 552654440 | E9: 420 | F9: CONJUNTO MANCAIS BLOCO | G9: 0 | H9: =+G9/E9 -> 0 | I9: =I8 -> 46120 | J9: =TODAY() -> 46118
A10: FIRE | B10: PROPULSION SOLUTIONS* | C10: 47104 | D10: 551812300 | E10: 120 | F10: POLIA CONDUZIDA EIXO MOTOR | G10: 0 | H10: =+G10/E10 -> 0 | I10: =I9 -> 46120 | J10: =TODAY() -> 46118
A11: FIRE | B11: PROPULSION SOLUTIONS* | C11: 47104 | D11: 551812330 | E11: 120 | F11: POLIA CONDUZIDA EIXO MOTOR - D | G11: 0 | H11: =+G11/E11 -> 0 | I11: =I10 -> 46120 | J11: =TODAY() -> 46118
A12: FIRE | B12: PROPULSION SOLUTIONS* | C12: 47104 | D12: 551812350 | E12: 120 | F12: POLIA CONDUZIDA EIXO MOTOR - A | G12: 0 | H12: =+G12/E12 -> 0 | I12: =I11 -> 46120 | J12: =TODAY() -> 46118
A13: FIRE | B13: PROPULSION SOLUTIONS* | C13: 47104 | D13: 551982470 | E13: 240 | F13: POLIA CONDUZIDA | G13: 0 | H13: =+G13/E13 -> 0 | I13: =I12 -> 46120 | J13: =TODAY() -> 46118
A14: FIRE | B14: LITENS - SP | C14: 47850 | D14: 552365200 | E14: 480 | F14: ROLAMENTO TENSOR CORREIA | G14: 0 | H14: =+G14/E14 -> 0 | I14: =I13 -> 46120 | J14: =TODAY() -> 46118
A15: FIRE | B15: LITENS - SP | C15: 47850 | D15: 552260560 | E15: 2000 | F15: ROLAMENTO TENSOR CORREIA | G15: 0 | H15: =+G15/E15 -> 0 | I15: =I14 -> 46120 | J15: =TODAY() -> 46118
A16: FIRE | B16: LITENS - SP | C16: 47850 | D16: 552002110 | E16: 480 | F16: ROLAMENTO TENSOR CORREIA | G16: 0 | H16: =+G16/E16 -> 0 | I16: =I15 -> 46120 | J16: =TODAY() -> 46118
... A103: TURBO | B103: APTIV MANUFATURA E SERVI. DE * | C103: 37866 | D103: 463564120 | E103: 60 | F103: CHICOTE DE INJECAO 281 T3 PL8 | G103: 0 | H103: =+G103/E103 -> 0 | I103: =I102 -> 46120 | J103: =TODAY() -> 46118
A104: TURBO | B104: APTIV MANUFATURA E SERVI. DE * | C104: 37866 | D104: 463577620 | E104: 60 | F104: CHICOTE DE INJECAO GSE T3 ACAC PL8 (CC21/CC22) | G104: 0 | H104: =+G104/E104 -> 0 | I104: =I96 -> 46120 | J104: =TODAY() -> 46118
A105: TURBO | B105: APTIV MANUFATURA E SERVI. DE * | C105: 37866 | D105: 463578580 | E105: 60 | F105: CHICOTE DE INJECAO T3 ACAC PL8 BSG (P21/P24) | G105: 0 | H105: =+G105/E105 -> 0 | I105: =I97 -> 46120 | J105: =TODAY() -> 46118
A106: TURBO | B106: APTIV MANUFATURA E SERVI. DE * | C106: 37866 | D106: 463603240 | E106: 60 | F106: CHICOTE DE INJECAO T4 - 7826 | G106: 0 | H106: =+G106/E106 -> 0 | I106: =I98 -> 46120 | J106: =TODAY() -> 46118
A107: TURBO | B107: APTIV MANUFATURA E SERVI. DE * | C107: 37866 | D107: 463576540 | E107: 60 | F107: CHICOTE DE INJECAO T4 376 PL8 | G107: 0 | H107: =+G107/E107 -> 0 | I107: =I98 -> 46120 | J107: =TODAY() -> 46118
A108: TURBO | B108: APTIV MANUFATURA E SERVI. DE * | C108: 37866 | D108: 463571180 | E108: 60 | F108: CHICOTE DE INJECAO T4 PL8 | G108: 0 | H108: =+G108/E108 -> 0 | I108: =I99 -> 46120 | J108: =TODAY() -> 46118
A109: TURBO | B109: CISER FIXADORES AUTOMOTIVOS S | C109: 27951 | D109: 463385060 | E109: 800 | F109: PARAFUSO BOMBA COMBUSTIVEL | G109: 0 | H109: =+G109/E109 -> 0 | I109: =I100 -> 46120 | J109: =TODAY() -> 46118
A110: TURBO | B110: CISER FIXADORES AUTOMOTIVOS S | C110: 27951 | D110: 552821660 | E110: 600 | F110: PARAFUSO DE FIXACAO - M6 X 18 | G110: 0 | H110: =+G110/E110 -> 0 | I110: =I101 -> 46120 | J110: =TODAY() -> 46118
A111: TURBO | B111: CISER FIXADORES AUTOMOTIVOS S | C111: 27951 | D111: 552822750 | E111: 300 | F111: PARAFUSO DE FIXACAO DA BOMBA D | G111: 0 | H111: =+G111/E111 -> 0 | I111: =I102 -> 46120 | J111: =TODAY() -> 46118
A112: TURBO | B112: CISER FIXADORES AUTOMOTIVOS S | C112: 27951 | D112: 552821670 | E112: 100 | F112: PARAFUSO ESPECIAL | G112: 0 | H112: =+G112/E112 -> 0 | I112: =I103 -> 46120 | J112: =TODAY() -> 46118
A113: TURBO | B113: CISER FIXADORES AUTOMOTIVOS S | C113: 27951 | D113: 552845970 | E113: 600 | F113: PARAFUSO ESPECIAL | G113: 0 | H113: =+G113/E113 -> 0 | I113: =I104 -> 46120 | J113: =TODAY() -> 46118
A114: TURBO | B114: CISER FIXADORES AUTOMOTIVOS S | C114: 27951 | D114: 552798810 | E114: 250 | F114: PARAFUSO ESPECIAL | G114: 0 | H114: =+G114/E114 -> 0 | I114: =I105 -> 46120 | J114: =TODAY() -> 46118
A115: TURBO | B115: CISER FIXADORES AUTOMOTIVOS S | C115: 27951 | D115: 552842340 | E115: 800 | F115: PARAFUSO ESPECIAL | G115: 0 | H115: =+G115/E115 -> 0 | I115: =I107 -> 46120 | J115: =TODAY() -> 46118
A116: TURBO | B116: CISER FIXADORES AUTOMOTIVOS S | C116: 27951 | D116: 552822630 | E116: 600 | F116: PARAFUSO ESPECIAL | G116: 0 | H116: =+G116/E116 -> 0 | I116: =I108 -> 46120 | J116: =TODAY() -> 46118
A117: TURBO | B117: CISER FIXADORES AUTOMOTIVOS S | C117: 27951 | D117: 552799020 | E117: 200 | F117: PARAFUSO ESPECIAL | G117: 0 | H117: =+G117/E117 -> 0 | I117: =I109 -> 46120 | J117: =TODAY() -> 46118
A118: TURBO | B118: CISER FIXADORES AUTOMOTIVOS S | C118: 27951 | D118: 463369240 | E118: 500 | F118: PARAFUSO ESPECIAL | G118: 0 | H118: =+G118/E118 -> 0 | I118: =I110 -> 46120 | J118: =TODAY() -> 46118
A119: TURBO | B119: CISER FIXADORES AUTOMOTIVOS S | C119: 27951 | D119: 463398780 | E119: 400 | F119: PARAFUSO ESPECIAL M6X46 | G119: 0 | H119: =+G119/E119 -> 0 | I119: =I111 -> 46120 | J119: =TODAY() -> 46118
A120: TURBO | B120: CISER FIXADORES AUTOMOTIVOS S | C120: 27951 | D120: 552822620 | E120: 800 | F120: PARAFUSO FIXACAO BOMBA DE AGUA | G120: 0 | H120: =+G120/E120 -> 0 | I120: =I112 -> 46120 | J120: =TODAY() -> 46118
A121: TURBO | B121: CISER FIXADORES AUTOMOTIVOS S | C121: 27951 | D121: 463473640 | E121: 500 | F121: PARAFUSO FIXACAO COLETOR | G121: 0 | H121: =+G121/E121 -> 0 | I121: =I113 -> 46120 | J121: =TODAY() -> 46118
A122: TURBO | B122: CISER FIXADORES AUTOMOTIVOS S | C122: 27951 | D122: 552831540 | E122: 400 | F122: PARAFUSO FIXACAO M6 X 40 | G122: 0 | H122: =+G122/E122 -> 0 | I122: =I114 -> 46120 | J122: =TODAY() -> 46118
A123: TURBO | B123: CISER FIXADORES AUTOMOTIVOS S | C123: 27951 | D123: 187517280 | E123: 400 | F123: PARAFUSO M6 X 37.5 | G123: 0 | H123: =+G123/E123 -> 0 | I123: =I115 -> 46120 | J123: =TODAY() -> 46118
A124: TURBO | B124: CISER FIXADORES AUTOMOTIVOS S | C124: 27951 | D124: 552822460 | E124: 650 | F124: PARAFUSO M6X14 | G124: 0 | H124: =+G124/E124 -> 0 | I124: =I116 -> 46120 | J124: =TODAY() -> 46118
A125: TURBO | B125: CISER FIXADORES AUTOMOTIVOS S | C125: 27951 | D125: 552821610 | E125: 150 | F125: PARAFUSO M8 X 80 | G125: 0 | H125: =+G125/E125 -> 0 | I125: =I117 -> 46120 | J125: =TODAY() -> 46118
A126: TURBO | B126: CISER FIXADORES AUTOMOTIVOS S | C126: 27951 | D126: 552842370 | E126: 400 | F126: PARAFUSO TE FLANGEADO M6X30 | G126: 0 | H126: =+G126/E126 -> 0 | I126: =I118 -> 46120 | J126: =TODAY() -> 46118
...

Sheet 16-02 SEG
A1: FIRE
A2: Saturação de Transporte
A3: PEDIDO | B3: FORNECEDOR | C3: CÓDIGO (IMS) | D3: DESENHO FIAT | E3: QME | F3: DENOMINAÇÃO | G3: QUANTIDADE SOLICITADA | H3: QUANTIDADE EMBALAGENS | I3: DATA DA COLETA | J3: DATA DA SOLICITAÇÃO | K3: HORÁRIO DA COLETA
A4: FIRE | B4: ALPINO SP | C4: 20419 | D4: 552540860 | E4: 525 | F4: TUBO RÍGIDO BOMBA D'AGUA | G4: 0 | H4: =+G4/E4 -> 0 | I4: 46069 | J4: 46066
A5: FIRE | B5: AUTOCAM -SP | C5: 19271 | D5: 552331860 | E5: 13800 | F5: TUCHO COMANDO DE VÁLVULAS | G5: 0 | H5: =+G5/E5 -> 0 | I5: 46069 | J5: 46066
A6: FIRE | B6: ALUDYNE - MG | C6: 29509 | D6: 552174870 | E6: 80 | F6: TAMPA DE VÁLVULA | G6: 0 | H6: =+G6/E6 -> 0 | I6: 46069 | J6: 46066
A7: FIRE | B7: ALUDYNE - SP | C7: 67200 | D7: 552322380 | E7: 1200 | F7: CONJUNTO MANCAIS CABEÇOTE | G7: 0 | H7: =+G7/E7 -> 0 | I7: 46069 | J7: 46066
A8: FIRE | B8: ALUDYNE - SP | C8: 67200 | D8: 552316530 | E8: 1200 | F8: CONJUNTO MANCAIS CABEÇOTE | G8: 0 | H8: =+G8/E8 -> 0 | I8: 46069 | J8: 46066
A9: FIRE | B9: ALUDYNE - SP | C9: 67200 | D9: 552654440 | E9: 420 | F9: CONJUNTO MANCAIS BLOCO | G9: 0 | H9: =+G9/E9 -> 0 | I9: 46069 | J9: 46066
A10: FIRE | B10: MUVIQ (PROPULSION/DAYCO) | C10: 47104 | D10: 551812300 | E10: 120 | F10: POLIA CONDUZIDA EIXO MOTOR | G10: 0 | H10: =+G10/E10 -> 0 | I10: 46069 | J10: 46066
A11: FIRE | B11: MUVIQ (PROPULSION/DAYCO) | C11: 47104 | D11: 551812330 | E11: 120 | F11: POLIA CONDUZIDA EIXO MOTOR - D | G11: 0 | H11: =+G11/E11 -> 0 | I11: 46069 | J11: 46066
A12: FIRE | B12: MUVIQ (PROPULSION/DAYCO) | C12: 47104 | D12: 551812350 | E12: 120 | F12: POLIA CONDUZIDA EIXO MOTOR - A | G12: 0 | H12: =+G12/E12 -> 0 | I12: 46069 | J12: 46066
A13: FIRE | B13: MUVIQ (PROPULSION/DAYCO) | C13: 47104 | D13: 551982470 | E13: 240 | F13: POLIA CONDUZIDA | G13: 0 | H13: =+G13/E13 -> 0 | I13: 46069 | J13: 46066
A14: FIRE | B14: LITENS - SP | C14: 47850 | D14: 552365200 | E14: 480 | F14: ROLAMENTO TENSOR CORREIA | G14: 0 | H14: =+G14/E14 -> 0 | I14: 46069 | J14: 46066
A15: FIRE | B15: LITENS - SP | C15: 47850 | D15: 552260560 | E15: 2000 | F15: ROLAMENTO TENSOR CORREIA | G15: 0 | H15: =+G15/E15 -> 0 | I15: 46069 | J15: 46066
... A184: TURBO | B184: MAHLE METAL LEVE S.A | C184: 15565 | D184: 463496640 | E184: 30 | F184: TAMPA CABECOTE MOTOR COMPLETA | G184: 0 | H184: =+G184/E184 -> 0 | I184: 46069 | J184: 46066
A185: TURBO | B185: ELRING KLINGER SP | C185: 31610 | D185: 463595330 | E185: 40 | F185: TAMPA DO CABEÇOTE T3 | G185: 0 | H185: 0 | I185: 46069 | J185: 46008
A186: TURBO | B186: ELRING KLINGER SP | C186: 31610 | D186: 552822380 | E186: 600 | F186: JUNTA METALOPLASTICA | G186: 0 | H186: =+G186/E186 -> 0 | I186: 46069 | J186: 46066
A187: TURBO | B187: ELRING KLINGER SP | C187: 31610 | D187: 463572030 | E187: 600 | F187: JUNTA CABECOTE MOTOR T3 | G187: 0 | H187: =+G187/E187 -> 0 | I187: 46069 | J187: 46066
A188: TURBO | B188: ELRING KLINGER SP | C188: 31610 | D188: 463572050 | E188: 600 | F188: JUNTA DA FLANGE COLETOR DESCARGA T3 | G188: 0 | H188: =+G188/E188 -> 0 | I188: 46069 | J188: 46066
A189: TURBO | B189: ELRING KLINGER SP | C189: 31610 | D189: 552823560 | E189: 600 | F189: JUNTA METALOPLASTICA T4 | G189: 0 | H189: =+G189/E189 -> 0 | I189: 46069 | J189: 46066
A190: TURBO | B190: ELRING KLINGER SP | C190: 31610 | D190: 463572040 | E190: 600 | F190: JUNTA CABECOTE MOTOR T4 | G190: 0 | H190: =+G190/E190 -> 0 | I190: 46069 | J190: 46066
A191: TURBO | B191: ELRING KLINGER SP | C191: 31610 | D191: 463595330 | E191: 600 | F191: JUNTA DA FLANGE COLETOR DESCARGA T4 | G191: 0 | H191: =+G191/E191 -> 0 | I191: 46069 | J191: 46066
A192: TURBO | B192: MUBEA DO BRASIL LTDA | C192: 50111 | D192: 552833910 | E192: 9000 | F192: MOLA PARA VALVULA | G192: 0 | H192: =+G192/E192 -> 0 | I192: 46069 | J192: 46066
A193: TURBO | B193: OMR - COMPONENTES AUTOMOTIVOS | C193: 56589 | D193: 463384907 | E193: 30 | F193: BLOCO MOTOR INFERIOR (BEDPLATE | G193: 900 | H193: =+G193/E193 -> 30 | I193: 46069 | J193: 46066
A194: TURBO | B194: OMR - COMPONENTES AUTOMOTIVOS | C194: 56589 | D194: 463384997 | E194: 30 | F194: BLOCO MOTOR INFERIOR T4 (BEDPL | G194: 600 | H194: =+G194/E194 -> 20 | I194: 46069 | J194: 46066
A195: TURBO | B195: METALKRAFT S/A SISTEMAS AUTOM | C195: 50050 | D195: 463529270 | E195: 432 | F195: CAPA MANCAL POSTERIOR DO CABEC | G195: 1296 | H195: =+G195/E195 -> 3 | I195: 46069 | J195: 46066
A196: TURBO | B196: NEUMAYER TEKFOR AUTOMOTIVE BR | C196: 30467 | D196: 552806540 | E196: 1200 | F196: PORCA | G196: 0 | H196: =+G196/E196 -> 0 | I196: 46069 | J196: 46066
A197: TURBO | B197: NEUMAYER TEKFOR AUTOMOTIVE BR | C197: 30467 | D197: 463389730 | E197: 400 | F197: PRISIONEIRO | G197: 0 | H197: =+G197/E197 -> 0 | I197: 46069 | J197: 46066
... A720: MECA | B720: OMR | C720: 56589 | D720: 463530718 | E720: 30 | F720: SUPORTE C513 GSE | G720: 0 | H720: =+G720/E720 -> 0 | I720: 46069 | J720: 46066

Sheet 17-02 TER
A1: FIRE
A2: Saturação de Transporte
A3: PEDIDO | B3: FORNECEDOR | C3: CÓDIGO (IMS) | D3: DESENHO FIAT | E3: QME | F3: DENOMINAÇÃO | G3: QUANTIDADE SOLICITADA | H3: QUANTIDADE EMBALAGENS | I3: DATA DA COLETA | J3: DATA DA SOLICITAÇÃO | K3: HORÁRIO DA COLETA
A4: FIRE | B4: ALPINO SP | C4: 20419 | D4: 552540860 | E4: 525 | F4: TUBO RÍGIDO BOMBA D'AGUA | G4: 0 | H4: =+G4/E4 -> 0 | I4: 46070 | J4: 46066
A5: FIRE | B5: AUTOCAM -SP | C5: 19271 | D5: 552331860 | E5: 13800 | F5: TUCHO COMANDO DE VÁLVULAS | G5: 0 | H5: =+G5/E5 -> 0 | I5: 46070 | J5: 46066
A6: FIRE | B6: ALUDYNE - MG | C6: 29509 | D6: 552174870 | E6: 80 | F6: TAMPA DE VÁLVULA | G6: 0 | H6: =+G6/E6 -> 0 | I6: 46070 | J6: 46066
A7: FIRE | B7: ALUDYNE - SP | C7: 67200 | D7: 552322380 | E7: 1200 | F7: CONJUNTO MANCAIS CABEÇOTE | G7: 0 | H7: =+G7/E7 -> 0 | I7: 46070 | J7: 46066
A8: FIRE | B8: ALUDYNE - SP | C8: 67200 | D8: 552316530 | E8: 1200 | F8: CONJUNTO MANCAIS CABEÇOTE | G8: 0 | H8: =+G8/E8 -> 0 | I8: 46070 | J8: 46066
A9: FIRE | B9: ALUDYNE - SP | C9: 67200 | D9: 552654440 | E9: 420 | F9: CONJUNTO MANCAIS BLOCO | G9: 0 | H9: =+G9/E9 -> 0 | I9: 46070 | J9: 46066
A10: FIRE | B10: MUVIQ (PROPULSION/DAYCO) | C10: 47104 | D10: 551812300 | E10: 120 | F10: POLIA CONDUZIDA EIXO MOTOR | G10: 0 | H10: =+G10/E10 -> 0 | I10: 46070 | J10: 46066
A11: FIRE | B11: MUVIQ (PROPULSION/DAYCO) | C11: 47104 | D11: 551812330 | E11: 120 | F11: POLIA CONDUZIDA EIXO MOTOR - D | G11: 0 | H11: =+G11/E11 -> 0 | I11: 46070 | J11: 46066
A12: FIRE | B12: MUVIQ (PROPULSION/DAYCO) | C12: 47104 | D12: 551812350 | E12: 120 | F12: POLIA CONDUZIDA EIXO MOTOR - A | G12: 0 | H12: =+G12/E12 -> 0 | I12: 46070 | J12: 46066
A13: FIRE | B13: MUVIQ (PROPULSION/DAYCO) | C13: 47104 | D13: 551982470 | E13: 240 | F13: POLIA CONDUZIDA | G13: 0 | H13: =+G13/E13 -> 0 | I13: 46070 | J13: 46066
A14: FIRE | B14: LITENS - SP | C14: 47850 | D14: 552365200 | E14: 480 | F14: ROLAMENTO TENSOR CORREIA | G14: 0 | H14: =+G14/E14 -> 0 | I14: 46070 | J14: 46066
A15: FIRE | B15: LITENS - SP | C15: 47850 | D15: 552260560 | E15: 2000 | F15: ROLAMENTO TENSOR CORREIA | G15: 0 | H15: =+G15/E15 -> 0 | I15: 46070 | J15: 46066
... A184: TURBO | B184: MAHLE METAL LEVE S.A | C184: 15565 | D184: 463496640 | E184: 30 | F184: TAMPA CABECOTE MOTOR COMPLETA | G184: 700 | H184: =+G184/E184 -> 23.333333 | I184: 46070 | J184: 46066
A185: TURBO | B185: ELRING KLINGER SP | C185: 31610 | D185: 463595330 | E185: 40 | F185: TAMPA DO CABEÇOTE T3 | G185: 0 | H185: 0 | I185: 46070 | J185: 46008
A186: TURBO | B186: ELRING KLINGER SP | C186: 31610 | D186: 552822380 | E186: 600 | F186: JUNTA METALOPLASTICA | G186: 0 | H186: =+G186/E186 -> 0 | I186: 46070 | J186: 46066
A187: TURBO | B187: ELRING KLINGER SP | C187: 31610 | D187: 463572030 | E187: 600 | F187: JUNTA CABECOTE MOTOR T3 | G187: 0 | H187: =+G187/E187 -> 0 | I187: 46070 | J187: 46066
A188: TURBO | B188: ELRING KLINGER SP | C188: 31610 | D188: 463572050 | E188: 600 | F188: JUNTA DA FLANGE COLETOR DESCARGA T3 | G188: 0 | H188: =+G188/E188 -> 0 | I188: 46070 | J188: 46066
A189: TURBO | B189: ELRING KLINGER SP | C189: 31610 | D189: 552823560 | E189: 600 | F189: JUNTA METALOPLASTICA T4 | G189: 0 | H189: =+G189/E189 -> 0 | I189: 46070 | J189: 46066
A190: TURBO | B190: ELRING KLINGER SP | C190: 31610 | D190: 463572040 | E190: 600 | F190: JUNTA CABECOTE MOTOR T4 | G190: 0 | H190: =+G190/E190 -> 0 | I190: 46070 | J190: 46066
A191: TURBO | B191: ELRING KLINGER SP | C191: 31610 | D191: 463595330 | E191: 600 | F191: JUNTA DA FLANGE COLETOR DESCARGA T4 | G191: 0 | H191: =+G191/E191 -> 0 | I191: 46070 | J191: 46066
A192: TURBO | B192: MUBEA DO BRASIL LTDA | C192: 50111 | D192: 552833910 | E192: 9000 | F192: MOLA PARA VALVULA | G192: 0 | H192: =+G192/E192 -> 0 | I192: 46070 | J192: 46066
A193: TURBO | B193: OMR - COMPONENTES AUTOMOTIVOS | C193: 56589 | D193: 463384907 | E193: 30 | F193: BLOCO MOTOR INFERIOR (BEDPLATE | G193: 600 | H193: =+G193/E193 -> 20 | I193: 46070 | J193: 46066
A194: TURBO | B194: OMR - COMPONENTES AUTOMOTIVOS | C194: 56589 | D194: 463384997 | E194: 30 | F194: BLOCO MOTOR INFERIOR T4 (BEDPL | G194: 600 | H194: =+G194/E194 -> 20 | I194: 46070 | J194: 46066
A195: TURBO | B195: METALKRAFT S/A SISTEMAS AUTOM | C195: 50050 | D195: 463529270 | E195: 432 | F195: CAPA MANCAL POSTERIOR DO CABEC | G195: 1728 | H195: =+G195/E195 -> 4 | I195: 46070 | J195: 46066
A196: TURBO | B196: NEUMAYER TEKFOR AUTOMOTIVE BR | C196: 30467 | D196: 552806540 | E196: 1200 | F196: PORCA | G196: 0 | H196: =+G196/E196 -> 0 | I196: 46070 | J196: 46066
A197: TURBO | B197: NEUMAYER TEKFOR AUTOMOTIVE BR | C197: 30467 | D197: 463389730 | E197: 400 | F197: PRISIONEIRO | G197: 0 | H197: =+G197/E197 -> 0 | I197: 46070 | J197: 46066
... A602: MECA | B602: AUTOCAM SJ | C602: 19271 | D602: 75810590 | E602: 900 | F602: ARRUELA (PRIMARIO) | G602: 0 | H602: =+G602/E602 -> 0 | I602: 46070 | J602: 46066
A603: MECA | B603: AUTOCAM SJ | C603: 19271 | D603: 465162750 | E603: 1620 | F603: ESPACADOR | G603: 1620 | H603: =+G603/E603 -> 1 | I603: 46070 | J603: 46066 | K603: Deixar no CDC 17:10h
A604: MECA | B604: AUTOCAM SJ | C604: 19271 | D604: 468147230 | E604: 1600 | F604: EIXO COMANDO EMBREAGEM | G604: 4800 | H604: =+G604/E604 -> 3 | I604: 46070 | J604: 46066 | K604: Deixar no CDC 17:10h
A605: MECA | B605: AUTOCAM SJ | C605: 19271 | D605: 552547090 | E605: 270 | F605: CONJUNTO ARVORE COMANDO COMPLE | G605: 0 | H605: =+G605/E605 -> 0 | I605: 46070 | J605: 46066
A606: MECA | B606: AUTOCAM SJ | C606: 19271 | D606: 552551360 | E606: 360 | F606: CONJUNTO ARVORE COMPLETA | G606: 0 | H606: =+G606/E606 -> 0 | I606: 46070 | J606: 46066
A607: MECA | B607: AUTOCAM SJ | C607: 19271 | D607: 735017020 | E607: 1440 | F607: EIXO MARCHA-RE | G607: 5760 | H607: =+G607/E607 -> 4 | I607: 46070 | J607: 46066 | K607: Deixar no CDC 17:10h
A608: MECA | B608: AUTOCAM SJ | C608: 19271 | D608: 552054650 | E608: 1440 | F608: PINO PORTA ENGRENAGEM SATELITE | G608: 2880 | H608: =+G608/E608 -> 2 | I608: 46070 | J608: 46066 | K608: Deixar no CDC 17:10h
A609: MECA | B609: AUTOCAM SJ | C609: 19271 | D609: 463409620 | E609: 360 | F609: CONJUNTO ARVORE COMPLETA | G609: 0 | H609: =+G609/E609 -> 0 | I609: 46070 | J609: 46066
A610: MECA | B610: AUTOCAM SJ | C610: 19271 | D610: 463409610 | E610: 360 | F610: CONJUNTO ARVORE COMPLETA COXINIZADA | G610: 5760 | H610: =+G610/E610 -> 16 | I610: 46070 | J610: 46066 | K610: Deixar no CDC 17:10h
A611: MECA | B611: AUTOMETAL | C611: 19807 | D611: 552594720 | E611: 900 | F611: GARFO COMANDO 1/2A VELOCIDADE | G611: 0 | H611: =+G611/E611 -> 0 | I611: 46070 | J611: 46066
A612: MECA | B612: AUTOMETAL | C612: 19807 | D612: 463602340 | E612: 900 | F612: GARFO COMANDO 3/4A VELOCIDADE | G612: 0 | H612: =+G612/E612 -> 0 | I612: 46070 | J612: 46066
...

Sheet 06-01-2026 Terça feira
A1: FIRE
A2: Saturação de Transporte
A3: PEDIDO | B3: FORNECEDOR | C3: CÓDIGO (IMS) | D3: DESENHO FIAT | E3: QME | F3: DENOMINAÇÃO | G3: QUANTIDADE SOLICITADA | H3: QUANTIDADE EMBALAGENS | I3: DATA DA COLETA | J3: DATA DA SOLICITAÇÃO | K3: HORÁRIO DA COLETA
A4: FIRE | B4: ALPINO SP | C4: 20419 | D4: 552540860 | E4: 525 | F4: TUBO RÍGIDO BOMBA D'AGUA | G4: 0 | H4: =+G4/E4 -> 0 | I4: =J4+1+4+1 -> 46124 | J4: =TODAY() -> 46118
A5: FIRE | B5: AUTOCAM -SP | C5: 19271 | D5: 552331860 | E5: 13800 | F5: TUCHO COMANDO DE VÁLVULAS | G5: 0 | H5: =+G5/E5 -> 0 | I5: =I4 -> 46124 | J5: =TODAY() -> 46118
A6: FIRE | B6: ALUDYNE - MG | C6: 29509 | D6: 552174870 | E6: 80 | F6: TAMPA DE VÁLVULA | G6: 0 | H6: =+G6/E6 -> 0 | I6: =I5 -> 46124 | J6: =TODAY() -> 46118
A7: FIRE | B7: ALUDYNE - SP | C7: 67200 | D7: 552322380 | E7: 1200 | F7: CONJUNTO MANCAIS CABEÇOTE | G7: 0 | H7: =+G7/E7 -> 0 | I7: =I6 -> 46124 | J7: =TODAY() -> 46118
A8: FIRE | B8: ALUDYNE - SP | C8: 67200 | D8: 552316530 | E8: 1200 | F8: CONJUNTO MANCAIS CABEÇOTE | G8: 0 | H8: =+G8/E8 -> 0 | I8: =I7 -> 46124 | J8: =TODAY() -> 46118
A9: FIRE | B9: ALUDYNE - SP | C9: 67200 | D9: 552654440 | E9: 420 | F9: CONJUNTO MANCAIS BLOCO | G9: 0 | H9: =+G9/E9 -> 0 | I9: =I8 -> 46124 | J9: =TODAY() -> 46118
A10: FIRE | B10: PROPULSION SOLUTIONS* | C10: 47104 | D10: 551812300 | E10: 120 | F10: POLIA CONDUZIDA EIXO MOTOR | G10: 0 | H10: =+G10/E10 -> 0 | I10: =I9 -> 46124 | J10: =TODAY() -> 46118
A11: FIRE | B11: PROPULSION SOLUTIONS* | C11: 47104 | D11: 551812330 | E11: 120 | F11: POLIA CONDUZIDA EIXO MOTOR - D | G11: 0 | H11: =+G11/E11 -> 0 | I11: =I10 -> 46124 | J11: =TODAY() -> 46118
A12: FIRE | B12: PROPULSION SOLUTIONS* | C12: 47104 | D12: 551812350 | E12: 120 | F12: POLIA CONDUZIDA EIXO MOTOR - A | G12: 0 | H12: =+G12/E12 -> 0 | I12: =I11 -> 46124 | J12: =TODAY() -> 46118
A13: FIRE | B13: PROPULSION SOLUTIONS* | C13: 47104 | D13: 551982470 | E13: 240 | F13: POLIA CONDUZIDA | G13: 0 | H13: =+G13/E13 -> 0 | I13: =I12 -> 46124 | J13: =TODAY() -> 46118
A14: FIRE | B14: LITENS - SP | C14: 47850 | D14: 552365200 | E14: 480 | F14: ROLAMENTO TENSOR CORREIA | G14: 0 | H14: =+G14/E14 -> 0 | I14: =I13 -> 46124 | J14: =TODAY() -> 46118
A15: FIRE | B15: LITENS - SP | C15: 47850 | D15: 552260560 | E15: 2000 | F15: ROLAMENTO TENSOR CORREIA | G15: 0 | H15: =+G15/E15 -> 0 | I15: =I14 -> 46124 | J15: =TODAY() -> 46118
A16: FIRE | B16: LITENS - SP | C16: 47850 | D16: 552002110 | E16: 480 | F16: ROLAMENTO TENSOR CORREIA | G16: 0 | H16: =+G16/E16 -> 0 | I16: =I15 -> 46124 | J16: =TODAY() -> 46118
... A103: TURBO | B103: APTIV MANUFATURA E SERVI. DE * | C103: 37866 | D103: 463564120 | E103: 60 | F103: CHICOTE DE INJECAO 281 T3 PL8 | G103: 0 | H103: =+G103/E103 -> 0 | I103: =I102 -> 46124 | J103: =TODAY() -> 46118
A104: TURBO | B104: APTIV MANUFATURA E SERVI. DE * | C104: 37866 | D104: 463577620 | E104: 60 | F104: CHICOTE DE INJECAO GSE T3 ACAC PL8 (CC21/CC22) | G104: 0 | H104: =+G104/E104 -> 0 | I104: =I96 -> 46124 | J104: =TODAY() -> 46118
A105: TURBO | B105: APTIV MANUFATURA E SERVI. DE * | C105: 37866 | D105: 463578580 | E105: 60 | F105: CHICOTE DE INJECAO T3 ACAC PL8 BSG (P21/P24) | G105: 0 | H105: =+G105/E105 -> 0 | I105: =I97 -> 46124 | J105: =TODAY() -> 46118
A106: TURBO | B106: APTIV MANUFATURA E SERVI. DE * | C106: 37866 | D106: 463576540 | E106: 60 | F106: CHICOTE DE INJECAO T4 376 PL8 | G106: 0 | H106: =+G106/E106 -> 0 | I106: =I98 -> 46124 | J106: =TODAY() -> 46118
A107: TURBO | B107: APTIV MANUFATURA E SERVI. DE * | C107: 37866 | D107: 463571180 | E107: 60 | F107: CHICOTE DE INJECAO T4 PL8 | G107: 0 | H107: =+G107/E107 -> 0 | I107: =I99 -> 46124 | J107: =TODAY() -> 46118
A108: TURBO | B108: CISER FIXADORES AUTOMOTIVOS S | C108: 27951 | D108: 463385060 | E108: 800 | F108: PARAFUSO BOMBA COMBUSTIVEL | G108: 0 | H108: =+G108/E108 -> 0 | I108: =I100 -> 46124 | J108: =TODAY() -> 46118
A109: TURBO | B109: CISER FIXADORES AUTOMOTIVOS S | C109: 27951 | D109: 552821660 | E109: 600 | F109: PARAFUSO DE FIXACAO - M6 X 18 | G109: 0 | H109: =+G109/E109 -> 0 | I109: =I101 -> 46124 | J109: =TODAY() -> 46118
A110: TURBO | B110: CISER FIXADORES AUTOMOTIVOS S | C110: 27951 | D110: 552822750 | E110: 300 | F110: PARAFUSO DE FIXACAO DA BOMBA D | G110: 0 | H110: =+G110/E110 -> 0 | I110: =I102 -> 46124 | J110: =TODAY() -> 46118
A111: TURBO | B111: CISER FIXADORES AUTOMOTIVOS S | C111: 27951 | D111: 552821670 | E111: 100 | F111: PARAFUSO ESPECIAL | G111: 0 | H111: =+G111/E111 -> 0 | I111: =I103 -> 46124 | J111: =TODAY() -> 46118
A112: TURBO | B112: CISER FIXADORES AUTOMOTIVOS S | C112: 27951 | D112: 552845970 | E112: 600 | F112: PARAFUSO ESPECIAL | G112: 0 | H112: =+G112/E112 -> 0 | I112: =I104 -> 46124 | J112: =TODAY() -> 46118
A113: TURBO | B113: CISER FIXADORES AUTOMOTIVOS S | C113: 27951 | D113: 552798810 | E113: 250 | F113: PARAFUSO ESPECIAL | G113: 0 | H113: =+G113/E113 -> 0 | I113: =I105 -> 46124 | J113: =TODAY() -> 46118
A114: TURBO | B114: CISER FIXADORES AUTOMOTIVOS S | C114: 27951 | D114: 552842340 | E114: 800 | F114: PARAFUSO ESPECIAL | G114: 0 | H114: =+G114/E114 -> 0 | I114: =I106 -> 46124 | J114: =TODAY() -> 46118
A115: TURBO | B115: CISER FIXADORES AUTOMOTIVOS S | C115: 27951 | D115: 552822630 | E115: 600 | F115: PARAFUSO ESPECIAL | G115: 0 | H115: =+G115/E115 -> 0 | I115: =I107 -> 46124 | J115: =TODAY() -> 46118
... A147: TURBO | B147: CONTINENTAL SP | C147: 36019 | D147: 463532650 | E147: 800 | F147: TAMPAO OBTURADOR | G147: 0 | H147: =+G147/E147 -> 0 | I147: =I139 -> 46124 | J147: =TODAY() -> 46118
A148: TURBO | B148: MAHLE METAL LEVE S.A | C148: 51658 | D148: 463485610 | E148: 600 | F148: BRONZINA DE BIELA STD. A | G148: 0 | H148: =+G148/E148 -> 0 | I148: =I121 -> 46124 | J148: =TODAY() -> 46118
A149: TURBO | B149: MAHLE METAL LEVE S.A | C149: 51658 | D149: 463485620 | E149: 600 | F149: BRONZINA DE BIELA STD. B | G149: 0 | H149: =+G149/E149 -> 0 | I149: =I122 -> 46124 | J149: =TODAY() -> 46118
A150: TURBO | B150: MAHLE METAL LEVE S.A | C150: 51658 | D150: 463485630 | E150: 600 | F150: BRONZINA DE BIELA STD. C | G150: 0 | H150: =+G150/E150 -> 0 | I150: =I123 -> 46124 | J150: =TODAY() -> 46118
A151: TURBO | B151: MAHLE METAL LEVE S.A | C151: 51658 | D151: 463485640 | E151: 600 | F151: BRONZINA DE BIELA SUPERIOR STD | G151: 0 | H151: =+G151/E151 -> 0 | I151: =I124 -> 46124 | J151: =TODAY() -> 46118
A152: TURBO | B152: MAHLE METAL LEVE S.A | C152: 51658 | D152: 463485650 | E152: 600 | F152: BRONZINA DE BIELA SUPERIOR STD | G152: 0 | H152: =+G152/E152 -> 0 | I152: =I125 -> 46124 | J152: =TODAY() -> 46118
A153: TURBO | B153: MAHLE METAL LEVE S.A | C153: 51658 | D153: 463485660 | E153: 600 | F153: BRONZINA DE BIELA SUPERIOR STD | G153: 0 | H153: =+G153/E153 -> 0 | I153: =I126 -> 46124 | J153: =TODAY() -> 46118
A154: TURBO | B154: MAHLE METAL LEVE S.A | C154: 51658 | D154: 463485380 | E154: 400 | F154: BRONZINA INFERIOR STD. A | G154: 0 | H154: =+G154/E154 -> 0 | I154: =I127 -> 46124 | J154: =TODAY() -> 46118
A155: TURBO | B155: MAHLE METAL LEVE S.A | C155: 51658 | D155: 463485390 | E155: 400 | F155: BRONZINA INFERIOR STD. B | G155: 0 | H155: =+G155/E155 -> 0 | I155: =I128 -> 46124 | J155: =TODAY() -> 46118
A156: TURBO | B156: MAHLE METAL LEVE S.A | C156: 51658 | D156: 463485400 | E156: 400 | F156: BRONZINA INFERIOR STD. C | G156: 0 | H156: =+G156/E156 -> 0 | I156: =I147 -> 46124 | J156: =TODAY() -> 46118
A157: TURBO | B157: MAHLE METAL LEVE S.A | C157: 51658 | D157: 463485440 | E157: 400 | F157: BRONZINA SUPERIOR STD. A | G157: 0 | H157: =+G157/E157 -> 0 | I157: =I149 -> 46124 | J157: =TODAY() -> 46118
...
